Workbook

Sheet summary
H1: 12月31日（实际 | J1: 1月2日（实际 | L1: 1月5日（实际 | N1: 1月6日（实际 | P1: 1月7日（实际 | T1: 1月8日（实际 | V1: 1月9日（实际 | X1: 1月12日（实际 | Z1: 1月13日（实际 | AB1: 1月14日（实际 | AF1: 1月15日（实际 | AH1: 1月16日（实际 | AJ1: 1月19日（实际 | AL1: 1月20日（实际 | AN1: 1月21日（实际 | AR1: 1月22日（实际 | AY1: 2026年02月24日 | BA1: 2026年02月26日 | BC1: 2026年02月26日 | BG1: 2025年08月01日 | BI1: 2025年12月05日 | BK1: 2026年02月24日 | BM1: 2025年09月12日 | BO1: 2025年06月23日 | BQ1: 2025年06月23日 | BS1: 2025年07月14日 | BU1: 2026年02月26日 | BW1: 2026年02月26日
B2: 參與者編號 | C2: 中央結算系統參與者名稱 | D2: 1月2日持股量 | E2: 1月3日持股量 | F2: 1月3日VS1月2日 | G2: 1月5日持股量 | H2: 1月5日VS1月3日 | I2: 1月6日持股量 | J2: 1月6日VS1月5日 | K2: 1月7日持股量 | L2: 1月7日VS1月6日 | M2: 1月8日持股量 | N2: 1月8日VS1月7日 | O2: 1月9日持股量 | P2: 1月9日VS1月8日 | Q2: 1月10日持股量 | R2: 1月10日VS1月9日 | S2: 1月12日持股量 | T2: 1月12日VS1月10日 | U2: 1月13日持股量 | V2: 1月13日VS1月12日 | W2: 1月14日持股量 | X2: 1月14日VS1月13日 | Y2: 1月15日持股量 | Z2: 1月15日VS1月14日 | AA2: 1月16日持股量 | AB2: 1月16日VS1月15日 | AC2: 1月17日持股量 | AD2: 1月17日VS1月16日 | AE2: 1月19日持股量 | AF2: 1月19日VS1月17日 | AG2: 1月20日持股量 | AH2: 1月20日VS1月19日 | AI2: 1月21日持股量 | AJ2: 1月21日VS1月20日 | AK2: 1月22日持股量 | AL2: 1月22日VS1月21日 | AM2: 1月23日持股量 | AN2: 1月23日VS1月22日 | AO2: 1月24日持股量 | AP2: 1月24日VS1月23日 | AQ2: 1月26日持股量 | AR2: 1月26日VS1月24日 | AS2: 2026年02月23日持股量 | AT2: 02月23日 VS1月26日 | AU2: 2026年02月24日持股量 | AV2: 02月24日 VS02月23日 | AW2: 2026年02月25日持股量 | AX2: 02月25日 VS02月24日 | AY2: 2026年02月26日持股量 | AZ2: 02月26日 VS02月25日 | BA2: 2026年03月02日持股量 | BB2: 03月02日 VS02月26日 | BC2: 2026年03月02日持股量 | BD2: 03月02日 VS03月02日 | BE2: 2025年12月09日持股量 | BF2: 12月09日 VS03月02日 | BG2: 2025年08月05日持股量 | BH2: 08月05日 VS12月09日 | BI2: 2025年12月09日持股量 | BJ2: 12月09日 VS08月05日 | BK2: 2026年02月26日持股量 | BL2: 02月26日 VS12月09日 | BM2: 2025年09月16日持股量 | BN2: 09月16日 VS02月26日 | BO2: 2025年06月25日持股量 | BP2: 06月25日 VS09月16日 | BQ2: 2025年06月25日持股量 | BR2: 06月25日 VS06月25日 | BS2: 2025年07月16日持股量 | BT2: 07月16日 VS06月25日 | BU2: 2026年03月02日持股量 | BV2: 03月02日 VS07月16日 | BW2: 2026年03月02日持股量 | BX2: 03月02日 VS03月02日
B3: C00019 | C3: 香港上海匯豐銀行有限公司 | D3: =_xlfn.IFNA(VLOOKUP($B3,'2026年1月2日'!$B:$E,4,0),0) | E3: =_xlfn.IFNA(VLOOKUP($B3,'2026年1月3日'!$B:$E,4,0),0) | F3: =E3-D3 | G3: =_xlfn.IFNA(VLOOKUP($B3,'2026年1月5日'!$B:$E,4,0),0) | H3: =G3-E3 | I3: =_xlfn.IFNA(VLOOKUP($B3,'2026年1月6日'!$B:$E,4,0),0) | J3: =I3-G3 | K3: =_xlfn.IFNA(VLOOKUP($B3,'2026年1月7日'!$B:$E,4,0),0) | L3: =K3-I3 | M3: =_xlfn.IFNA(VLOOKUP($B3,'2026年1月8日'!$B:$E,4,0),0) | N3: =M3-K3 | O3: =_xlfn.IFNA(VLOOKUP($B3,'2026年1月9日'!$B:$E,4,0),0) | P3: =O3-M3 | Q3: =_xlfn.IFNA(VLOOKUP($B3,'2026年1月10日'!$B:$E,4,0),0) | R3: =Q3-O3 | S3: =_xlfn.IFNA(VLOOKUP($B3,'2026年1月12日'!$B:$E,4,0),0) | T3: =S3-Q3 | U3: =_xlfn.IFNA(VLOOKUP($B3,'2026年1月13日'!$B:$E,4,0),0) | V3: =U3-S3 | W3: =_xlfn.IFNA(VLOOKUP($B3,'2026年1月14日'!$B:$E,4,0),0) | X3: =W3-U3 | Y3: =_xlfn.IFNA(VLOOKUP($B3,'2026年1月15日'!$B:$E,4,0),0) | Z3: =Y3-W3 | AA3: =_xlfn.IFNA(VLOOKUP($B3,'2026年1月16日'!$B:$E,4,0),0) | AB3: =AA3-Y3 | AC3: =_xlfn.IFNA(VLOOKUP($B3,'2026年1月17日'!$B:$E,4,0),0) | AD3: =AC3-AA3 | AE3: =_xlfn.IFNA(VLOOKUP($B3,'2026年1月19日'!$B:$E,4,0),0) | AF3: =AE3-AC3 | AG3: =_xlfn.IFNA(VLOOKUP($B3,'2026年1月20日'!$B:$E,4,0),0) | AH3: =AG3-AE3 | AI3: =_xlfn.IFNA(VLOOKUP($B3,'2026年1月21日'!$B:$E,4,0),0) | AJ3: =AI3-AG3 | AK3: =_xlfn.IFNA(VLOOKUP($B3,'2026年1月22日'!$B:$E,4,0),0) | AL3: =AK3-AI3 | AM3: =_xlfn.IFNA(VLOOKUP($B3,'2026年1月23日'!$B:$E,4,0),0) | AN3: =AM3-AK3 | AO3: =_xlfn.IFNA(VLOOKUP($B3,'2026年1月24日'!$B:$E,4,0),0) | AP3: =AO3-AM3 | AQ3: =_xlfn.IFNA(VLOOKUP($B3,'2026年1月26日'!$B:$E,4,0),0) | AR3: =AQ3-AO3 | AS3: 132692081 | AU3: 133000181 | AV3: 308100 | AW3: 133273799 | AX3: 273618 | AY3: 131170184 | AZ3: -2103615 | BA3: 129426200 | BB3: -1743984 | BC3: 130124247 | BD3: 698047 | BE3: 118322617 | BF3: -11801630 | BG3: 130559200 | BH3: 12236583 | BI3: 118322617 | BJ3: -12236583 | BK3: 131170184 | BL3: 12847567 | BM3: 134681115 | BN3: 3510931 | BO3: 129147620 | BP3: -5533495 | BQ3: 129147620 | BR3: 0 | BS3: 116350356 | BT3: -12797264 | BU3: 129426200 | BV3: 13075844 | BW3: 129426200 | BX3: 0
B4: A00004 | C4: CHINA SECURITIES DEPOSITORY AND CLEARING | D4: =_xlfn.IFNA(VLOOKUP($B4,'2026年1月2日'!$B:$E,4,0),0) | E4: =_xlfn.IFNA(VLOOKUP($B4,'2026年1月2日'!$B:$E,4,0),0) | F4: =E4-D4 | G4: =_xlfn.IFNA(VLOOKUP($B4,'2026年1月5日'!$B:$E,4,0),0) | H4: =G4-E4 | I4: =_xlfn.IFNA(VLOOKUP($B4,'2026年1月6日'!$B:$E,4,0),0) | J4: =I4-G4 | K4: =_xlfn.IFNA(VLOOKUP($B4,'2026年1月7日'!$B:$E,4,0),0) | L4: =K4-I4 | M4: =_xlfn.IFNA(VLOOKUP($B4,'2026年1月8日'!$B:$E,4,0),0) | N4: =M4-K4 | O4: =_xlfn.IFNA(VLOOKUP($B4,'2026年1月9日'!$B:$E,4,0),0) | P4: =O4-M4 | Q4: =_xlfn.IFNA(VLOOKUP($B4,'2026年1月10日'!$B:$E,4,0),0) | R4: =Q4-O4 | S4: =_xlfn.IFNA(VLOOKUP($B4,'2026年1月12日'!$B:$E,4,0),0) | T4: =S4-Q4 | U4: =_xlfn.IFNA(VLOOKUP($B4,'2026年1月13日'!$B:$E,4,0),0) | V4: =U4-S4 | W4: =_xlfn.IFNA(VLOOKUP($B4,'2026年1月14日'!$B:$E,4,0),0) | X4: =W4-U4 | Y4: =_xlfn.IFNA(VLOOKUP($B4,'2026年1月15日'!$B:$E,4,0),0) | Z4: =Y4-W4 | AA4: =_xlfn.IFNA(VLOOKUP($B4,'2026年1月16日'!$B:$E,4,0),0) | AB4: =AA4-W4 | AC4: =_xlfn.IFNA(VLOOKUP($B4,'2026年1月17日'!$B:$E,4,0),0) | AD4: =AC4-AA4 | AE4: =_xlfn.IFNA(VLOOKUP($B4,'2026年1月19日'!$B:$E,4,0),0) | AF4: =AE4-AC4 | AG4: =_xlfn.IFNA(VLOOKUP($B4,'2026年1月20日'!$B:$E,4,0),0) | AH4: =AG4-AE4 | AI4: =_xlfn.IFNA(VLOOKUP($B4,'2026年1月21日'!$B:$E,4,0),0) | AJ4: =AI4-AG4 | AK4: =_xlfn.IFNA(VLOOKUP($B4,'2026年1月22日'!$B:$E,4,0),0) | AL4: =AK4-AI4 | AM4: =_xlfn.IFNA(VLOOKUP($B4,'2026年1月23日'!$B:$E,4,0),0) | AN4: =AM4-AK4 | AO4: =_xlfn.IFNA(VLOOKUP($B4,'2026年1月24日'!$B:$E,4,0),0) | AP4: =AO4-AM4 | AQ4: =_xlfn.IFNA(VLOOKUP($B4,'2026年1月26日'!$B:$E,4,0),0) | AR4: =AQ4-AO4 | AS4: 91218748 | AU4: 91218748 | AV4: 0 | AW4: 91218748 | AX4: 0 | AY4: 92029348 | AZ4: 810600 | BA4: 93232548 | BB4: 1203200 | BC4: 92868848 | BD4: -363700 | BE4: 95039348 | BF4: 2170500 | BG4: 70290634 | BH4: -24748714 | BI4: 95039348 | BJ4: 24748714 | BK4: 92029348 | BL4: -3010000 | BM4: 81468734 | BN4: -10560614 | BO4: 75013234 | BP4: -6455500 | BQ4: 75013234 | BR4: 0 | BS4: 75026034 | BT4: 12800 | BU4: 93232548 | BV4: 18206514 | BW4: 93232548 | BX4: 0
B5: B01955 | C5: 富途證券國際(香港)有限公司 | D5: =_xlfn.IFNA(VLOOKUP($B5,'2026年1月2日'!$B:$E,4,0),0) | E5: =_xlfn.IFNA(VLOOKUP($B5,'2026年1月2日'!$B:$E,4,0),0) | F5: =E5-D5 | G5: =_xlfn.IFNA(VLOOKUP($B5,'2026年1月5日'!$B:$E,4,0),0) | H5: =G5-E5 | I5: =_xlfn.IFNA(VLOOKUP($B5,'2026年1月6日'!$B:$E,4,0),0) | J5: =I5-G5 | K5: =_xlfn.IFNA(VLOOKUP($B5,'2026年1月7日'!$B:$E,4,0),0) | L5: =K5-I5 | M5: =_xlfn.IFNA(VLOOKUP($B5,'2026年1月8日'!$B:$E,4,0),0) | N5: =M5-K5 | O5: =_xlfn.IFNA(VLOOKUP($B5,'2026年1月9日'!$B:$E,4,0),0) | P5: =O5-M5 | Q5: =_xlfn.IFNA(VLOOKUP($B5,'2026年1月10日'!$B:$E,4,0),0) | R5: =Q5-O5 | S5: =_xlfn.IFNA(VLOOKUP($B5,'2026年1月12日'!$B:$E,4,0),0) | T5: =S5-Q5 | U5: =_xlfn.IFNA(VLOOKUP($B5,'2026年1月13日'!$B:$E,4,0),0) | V5: =U5-S5 | W5: =_xlfn.IFNA(VLOOKUP($B5,'2026年1月14日'!$B:$E,4,0),0) | X5: =W5-U5 | Y5: =_xlfn.IFNA(VLOOKUP($B5,'2026年1月15日'!$B:$E,4,0),0) | Z5: =Y5-W5 | AA5: =_xlfn.IFNA(VLOOKUP($B5,'2026年1月16日'!$B:$E,4,0),0) | AB5: =AA5-W5 | AC5: =_xlfn.IFNA(VLOOKUP($B5,'2026年1月17日'!$B:$E,4,0),0) | AD5: =AC5-AA5 | AE5: =_xlfn.IFNA(VLOOKUP($B5,'2026年1月19日'!$B:$E,4,0),0) | AF5: =AE5-AC5 | AG5: =_xlfn.IFNA(VLOOKUP($B5,'2026年1月20日'!$B:$E,4,0),0) | AH5: =AG5-AE5 | AI5: =_xlfn.IFNA(VLOOKUP($B5,'2026年1月21日'!$B:$E,4,0),0) | AJ5: =AI5-AG5 | AK5: =_xlfn.IFNA(VLOOKUP($B5,'2026年1月22日'!$B:$E,4,0),0) | AL5: =AK5-AI5 | AM5: =_xlfn.IFNA(VLOOKUP($B5,'2026年1月23日'!$B:$E,4,0),0) | AN5: =AM5-AK5 | AO5: =_xlfn.IFNA(VLOOKUP($B5,'2026年1月24日'!$B:$E,4,0),0) | AP5: =AO5-AM5 | AQ5: =_xlfn.IFNA(VLOOKUP($B5,'2026年1月26日'!$B:$E,4,0),0) | AR5: =AQ5-AO5 | AS5: 44421885 | AU5: 44644385 | AV5: 222500 | AW5: 44505885 | AX5: -138500 | AY5: 44915985 | AZ5: 410100 | BA5: 45951335 | BB5: 1035350 | BC5: 45997935 | BD5: 46600 | BE5: 46443241 | BF5: 445306 | BG5: 44455884 | BH5: -1987357 | BI5: 46443241 | BJ5: 1987357 | BK5: 44915985 | BL5: -1527256 | BM5: 50611056 | BN5: 5695071 | BO5: 43584404 | BP5: -7026652 | BQ5: 43584404 | BR5: 0 | BS5: 46479609 | BT5: 2895205 | BU5: 45951335 | BV5: -528274 | BW5: 45951335 | BX5: 0
B6: A00003 | C6: 中國証券登記結算有限責任公司 | D6: =_xlfn.IFNA(VLOOKUP($B6,'2026年1月2日'!$B:$E,4,0),0) | E6: =_xlfn.IFNA(VLOOKUP($B6,'2026年1月2日'!$B:$E,4,0),0) | F6: =E6-D6 | G6: =_xlfn.IFNA(VLOOKUP($B6,'2026年1月5日'!$B:$E,4,0),0) | H6: =G6-E6 | I6: =_xlfn.IFNA(VLOOKUP($B6,'2026年1月6日'!$B:$E,4,0),0) | J6: =I6-G6 | K6: =_xlfn.IFNA(VLOOKUP($B6,'2026年1月7日'!$B:$E,4,0),0) | L6: =K6-I6 | M6: =_xlfn.IFNA(VLOOKUP($B6,'2026年1月8日'!$B:$E,4,0),0) | N6: =M6-K6 | O6: =_xlfn.IFNA(VLOOKUP($B6,'2026年1月9日'!$B:$E,4,0),0) | P6: =O6-M6 | Q6: =_xlfn.IFNA(VLOOKUP($B6,'2026年1月10日'!$B:$E,4,0),0) | R6: =Q6-O6 | S6: =_xlfn.IFNA(VLOOKUP($B6,'2026年1月12日'!$B:$E,4,0),0) | T6: =S6-Q6 | U6: =_xlfn.IFNA(VLOOKUP($B6,'2026年1月13日'!$B:$E,4,0),0) | V6: =U6-S6 | W6: =_xlfn.IFNA(VLOOKUP($B6,'2026年1月14日'!$B:$E,4,0),0) | X6: =W6-U6 | Y6: =_xlfn.IFNA(VLOOKUP($B6,'2026年1月15日'!$B:$E,4,0),0) | Z6: =Y6-W6 | AA6: =_xlfn.IFNA(VLOOKUP($B6,'2026年1月16日'!$B:$E,4,0),0) | AB6: =AA6-W6 | AC6: =_xlfn.IFNA(VLOOKUP($B6,'2026年1月17日'!$B:$E,4,0),0) | AD6: =AC6-AA6 | AE6: =_xlfn.IFNA(VLOOKUP($B6,'2026年1月19日'!$B:$E,4,0),0) | AF6: =AE6-AC6 | AG6: =_xlfn.IFNA(VLOOKUP($B6,'2026年1月20日'!$B:$E,4,0),0) | AH6: =AG6-AE6 | AI6: =_xlfn.IFNA(VLOOKUP($B6,'2026年1月21日'!$B:$E,4,0),0) | AJ6: =AI6-AG6 | AK6: =_xlfn.IFNA(VLOOKUP($B6,'2026年1月22日'!$B:$E,4,0),0) | AL6: =AK6-AI6 | AM6: =_xlfn.IFNA(VLOOKUP($B6,'2026年1月23日'!$B:$E,4,0),0) | AN6: =AM6-AK6 | AO6: =_xlfn.IFNA(VLOOKUP($B6,'2026年1月24日'!$B:$E,4,0),0) | AP6: =AO6-AM6 | AQ6: =_xlfn.IFNA(VLOOKUP($B6,'2026年1月26日'!$B:$E,4,0),0) | AR6: =AQ6-AO6 | AS6: 151148600 | AU6: 151148600 | AV6: 0 | AW6: 151148600 | AX6: 0 | AY6: 150844100 | AZ6: -304500 | BA6: 151646900 | BB6: 802800 | BC6: 151083800 | BD6: -563100 | BE6: 157431800 | BF6: 6348000 | BG6: 128024900 | BH6: -29406900 | BI6: 157431800 | BJ6: 29406900 | BK6: 150844100 | BL6: -6587700 | BM6: 133048500 | BN6: -17795600 | BO6: 124071600 | BP6: -8976900 | BQ6: 124071600 | BR6: 0 | BS6: 134887100 | BT6: 10815500 | BU6: 151646900 | BV6: 16759800 | BW6: 151646900 | BX6: 0
B7: B01451 | C7: 高盛(亞洲)證券有限公司 | D7: =_xlfn.IFNA(VLOOKUP($B7,'2026年1月2日'!$B:$E,4,0),0) | E7: =_xlfn.IFNA(VLOOKUP($B7,'2026年1月2日'!$B:$E,4,0),0) | F7: =E7-D7 | G7: =_xlfn.IFNA(VLOOKUP($B7,'2026年1月5日'!$B:$E,4,0),0) | H7: =G7-E7 | I7: =_xlfn.IFNA(VLOOKUP($B7,'2026年1月6日'!$B:$E,4,0),0) | J7: =I7-G7 | K7: =_xlfn.IFNA(VLOOKUP($B7,'2026年1月7日'!$B:$E,4,0),0) | L7: =K7-I7 | M7: =_xlfn.IFNA(VLOOKUP($B7,'2026年1月8日'!$B:$E,4,0),0) | N7: =M7-K7 | O7: =_xlfn.IFNA(VLOOKUP($B7,'2026年1月9日'!$B:$E,4,0),0) | P7: =O7-M7 | Q7: =_xlfn.IFNA(VLOOKUP($B7,'2026年1月10日'!$B:$E,4,0),0) | R7: =Q7-O7 | S7: =_xlfn.IFNA(VLOOKUP($B7,'2026年1月12日'!$B:$E,4,0),0) | T7: =S7-Q7 | U7: =_xlfn.IFNA(VLOOKUP($B7,'2026年1月13日'!$B:$E,4,0),0) | V7: =U7-S7 | W7: =_xlfn.IFNA(VLOOKUP($B7,'2026年1月14日'!$B:$E,4,0),0) | X7: =W7-U7 | Y7: =_xlfn.IFNA(VLOOKUP($B7,'2026年1月15日'!$B:$E,4,0),0) | Z7: =Y7-W7 | AA7: =_xlfn.IFNA(VLOOKUP($B7,'2026年1月16日'!$B:$E,4,0),0) | AB7: =AA7-W7 | AC7: =_xlfn.IFNA(VLOOKUP($B7,'2026年1月17日'!$B:$E,4,0),0) | AD7: =AC7-AA7 | AE7: =_xlfn.IFNA(VLOOKUP($B7,'2026年1月19日'!$B:$E,4,0),0) | AF7: =AE7-AC7 | AG7: =_xlfn.IFNA(VLOOKUP($B7,'2026年1月20日'!$B:$E,4,0),0) | AH7: =AG7-AE7 | AI7: =_xlfn.IFNA(VLOOKUP($B7,'2026年1月21日'!$B:$E,4,0),0) | AJ7: =AI7-AG7 | AK7: =_xlfn.IFNA(VLOOKUP($B7,'2026年1月22日'!$B:$E,4,0),0) | AL7: =AK7-AI7 | AM7: =_xlfn.IFNA(VLOOKUP($B7,'2026年1月23日'!$B:$E,4,0),0) | AN7: =AM7-AK7 | AO7: =_xlfn.IFNA(VLOOKUP($B7,'2026年1月24日'!$B:$E,4,0),0) | AP7: =AO7-AM7 | AQ7: =_xlfn.IFNA(VLOOKUP($B7,'2026年1月26日'!$B:$E,4,0),0) | AR7: =AQ7-AO7 | AS7: 39729324 | AU7: 39728624 | AV7: -700 | AW7: 39728424 | AX7: -200 | AY7: 39728524 | AZ7: 100 | BA7: 39728405 | BB7: -119 | BC7: 39728405 | BD7: 0 | BE7: 30238705 | BF7: -9489700 | BG7: 27050205 | BH7: -3188500 | BI7: 30238705 | BJ7: 3188500 | BK7: 39728524 | BL7: 9489819 | BM7: 45772375 | BN7: 6043851 | BO7: 27058905 | BP7: -18713470 | BQ7: 27058905 | BR7: 0 | BS7: 27267205 | BT7: 208300 | BU7: 39728405 | BV7: 12461200 | BW7: 39728405 | BX7: 0
B8: B01274 | C8: MORGAN STANLEY HONG KONG SECURITIES LTD | D8: =_xlfn.IFNA(VLOOKUP($B8,'2026年1月2日'!$B:$E,4,0),0) | E8: =_xlfn.IFNA(VLOOKUP($B8,'2026年1月2日'!$B:$E,4,0),0) | F8: =E8-D8 | G8: =_xlfn.IFNA(VLOOKUP($B8,'2026年1月5日'!$B:$E,4,0),0) | H8: =G8-E8 | I8: =_xlfn.IFNA(VLOOKUP($B8,'2026年1月6日'!$B:$E,4,0),0) | J8: =I8-G8 | K8: =_xlfn.IFNA(VLOOKUP($B8,'2026年1月7日'!$B:$E,4,0),0) | L8: =K8-I8 | M8: =_xlfn.IFNA(VLOOKUP($B8,'2026年1月8日'!$B:$E,4,0),0) | N8: =M8-K8 | O8: =_xlfn.IFNA(VLOOKUP($B8,'2026年1月9日'!$B:$E,4,0),0) | P8: =O8-M8 | Q8: =_xlfn.IFNA(VLOOKUP($B8,'2026年1月10日'!$B:$E,4,0),0) | R8: =Q8-O8 | S8: =_xlfn.IFNA(VLOOKUP($B8,'2026年1月12日'!$B:$E,4,0),0) | T8: =S8-Q8 | U8: =_xlfn.IFNA(VLOOKUP($B8,'2026年1月13日'!$B:$E,4,0),0) | V8: =U8-S8 | W8: =_xlfn.IFNA(VLOOKUP($B8,'2026年1月14日'!$B:$E,4,0),0) | X8: =W8-U8 | Y8: =_xlfn.IFNA(VLOOKUP($B8,'2026年1月15日'!$B:$E,4,0),0) | Z8: =Y8-W8 | AA8: =_xlfn.IFNA(VLOOKUP($B8,'2026年1月16日'!$B:$E,4,0),0) | AB8: =AA8-W8 | AC8: =_xlfn.IFNA(VLOOKUP($B8,'2026年1月17日'!$B:$E,4,0),0) | AD8: =AC8-AA8 | AE8: =_xlfn.IFNA(VLOOKUP($B8,'2026年1月19日'!$B:$E,4,0),0) | AF8: =AE8-AC8 | AG8: =_xlfn.IFNA(VLOOKUP($B8,'2026年1月20日'!$B:$E,4,0),0) | AH8: =AG8-AE8 | AI8: =_xlfn.IFNA(VLOOKUP($B8,'2026年1月21日'!$B:$E,4,0),0) | AJ8: =AI8-AG8 | AK8: =_xlfn.IFNA(VLOOKUP($B8,'2026年1月22日'!$B:$E,4,0),0) | AL8: =AK8-AI8 | AM8: =_xlfn.IFNA(VLOOKUP($B8,'2026年1月23日'!$B:$E,4,0),0) | AN8: =AM8-AK8 | AO8: =_xlfn.IFNA(VLOOKUP($B8,'2026年1月24日'!$B:$E,4,0),0) | AP8: =AO8-AM8 | AQ8: =_xlfn.IFNA(VLOOKUP($B8,'2026年1月26日'!$B:$E,4,0),0) | AR8: =AQ8-AO8 | AS8: 2517378 | AU8: 2603327 | AV8: 85949 | AW8: 2649827 | AX8: 46500 | AY8: 2545370 | AZ8: -104457 | BA8: 2505717 | BB8: -39653 | BE8: 2745550 | BG8: 2404549 | BH8: -341001 | BI8: 2745550 | BJ8: 341001 | BK8: 2545370 | BL8: -200180 | BM8: 2951598 | BN8: 406228 | BO8: 4596952 | BP8: 1645354 | BQ8: 4596952 | BR8: 0 | BS8: 4606849 | BT8: 9897 | BU8: 2505717 | BV8: -2101132 | BW8: 2505717 | BX8: 0
B9: C00100 | C9: JPMORGAN CHASE BANK, NATIONAL ASSOCIATION | D9: =_xlfn.IFNA(VLOOKUP($B9,'2026年1月2日'!$B:$E,4,0),0) | E9: =_xlfn.IFNA(VLOOKUP($B9,'2026年1月2日'!$B:$E,4,0),0) | F9: =E9-D9 | G9: =_xlfn.IFNA(VLOOKUP($B9,'2026年1月5日'!$B:$E,4,0),0) | H9: =G9-E9 | I9: =_xlfn.IFNA(VLOOKUP($B9,'2026年1月6日'!$B:$E,4,0),0) | J9: =I9-G9 | K9: =_xlfn.IFNA(VLOOKUP($B9,'2026年1月7日'!$B:$E,4,0),0) | L9: =K9-I9 | M9: =_xlfn.IFNA(VLOOKUP($B9,'2026年1月8日'!$B:$E,4,0),0) | N9: =M9-K9 | O9: =_xlfn.IFNA(VLOOKUP($B9,'2026年1月9日'!$B:$E,4,0),0) | P9: =O9-M9 | Q9: =_xlfn.IFNA(VLOOKUP($B9,'2026年1月10日'!$B:$E,4,0),0) | R9: =Q9-O9 | S9: =_xlfn.IFNA(VLOOKUP($B9,'2026年1月12日'!$B:$E,4,0),0) | T9: =S9-Q9 | U9: =_xlfn.IFNA(VLOOKUP($B9,'2026年1月13日'!$B:$E,4,0),0) | V9: =U9-S9 | W9: =_xlfn.IFNA(VLOOKUP($B9,'2026年1月14日'!$B:$E,4,0),0) | X9: =W9-U9 | Y9: =_xlfn.IFNA(VLOOKUP($B9,'2026年1月15日'!$B:$E,4,0),0) | Z9: =Y9-W9 | AA9: =_xlfn.IFNA(VLOOKUP($B9,'2026年1月16日'!$B:$E,4,0),0) | AB9: =AA9-W9 | AC9: =_xlfn.IFNA(VLOOKUP($B9,'2026年1月17日'!$B:$E,4,0),0) | AD9: =AC9-AA9 | AE9: =_xlfn.IFNA(VLOOKUP($B9,'2026年1月19日'!$B:$E,4,0),0) | AF9: =AE9-AC9 | AG9: =_xlfn.IFNA(VLOOKUP($B9,'2026年1月20日'!$B:$E,4,0),0) | AH9: =AG9-AE9 | AI9: =_xlfn.IFNA(VLOOKUP($B9,'2026年1月21日'!$B:$E,4,0),0) | AJ9: =AI9-AG9 | AK9: =_xlfn.IFNA(VLOOKUP($B9,'2026年1月22日'!$B:$E,4,0),0) | AL9: =AK9-AI9 | AM9: =_xlfn.IFNA(VLOOKUP($B9,'2026年1月23日'!$B:$E,4,0),0) | AN9: =AM9-AK9 | AO9: =_xlfn.IFNA(VLOOKUP($B9,'2026年1月24日'!$B:$E,4,0),0) | AP9: =AO9-AM9 | AQ9: =_xlfn.IFNA(VLOOKUP($B9,'2026年1月26日'!$B:$E,4,0),0) | AR9: =AQ9-AO9
B10: C00033 | C10: 中國銀行(香港)有限公司 | D10: =_xlfn.IFNA(VLOOKUP($B10,'2026年1月2日'!$B:$E,4,0),0) | E10: =_xlfn.IFNA(VLOOKUP($B10,'2026年1月2日'!$B:$E,4,0),0) | F10: =E10-D10 | G10: =_xlfn.IFNA(VLOOKUP($B10,'2026年1月5日'!$B:$E,4,0),0) | H10: =G10-E10 | I10: =_xlfn.IFNA(VLOOKUP($B10,'2026年1月6日'!$B:$E,4,0),0) | J10: =I10-G10 | K10: =_xlfn.IFNA(VLOOKUP($B10,'2026年1月7日'!$B:$E,4,0),0) | L10: =K10-I10 | M10: =_xlfn.IFNA(VLOOKUP($B10,'2026年1月8日'!$B:$E,4,0),0) | N10: =M10-K10 | O10: =_xlfn.IFNA(VLOOKUP($B10,'2026年1月9日'!$B:$E,4,0),0) | P10: =O10-M10 | Q10: =_xlfn.IFNA(VLOOKUP($B10,'2026年1月10日'!$B:$E,4,0),0) | R10: =Q10-O10 | S10: =_xlfn.IFNA(VLOOKUP($B10,'2026年1月12日'!$B:$E,4,0),0) | T10: =S10-Q10 | U10: =_xlfn.IFNA(VLOOKUP($B10,'2026年1月13日'!$B:$E,4,0),0) | V10: =U10-S10 | W10: =_xlfn.IFNA(VLOOKUP($B10,'2026年1月14日'!$B:$E,4,0),0) | X10: =W10-U10 | Y10: =_xlfn.IFNA(VLOOKUP($B10,'2026年1月15日'!$B:$E,4,0),0) | Z10: =Y10-W10 | AA10: =_xlfn.IFNA(VLOOKUP($B10,'2026年1月16日'!$B:$E,4,0),0) | AB10: =AA10-W10 | AC10: =_xlfn.IFNA(VLOOKUP($B10,'2026年1月17日'!$B:$E,4,0),0) | AD10: =AC10-AA10 | AE10: =_xlfn.IFNA(VLOOKUP($B10,'2026年1月19日'!$B:$E,4,0),0) | AF10: =AE10-AC10 | AG10: =_xlfn.IFNA(VLOOKUP($B10,'2026年1月20日'!$B:$E,4,0),0) | AH10: =AG10-AE10 | AI10: =_xlfn.IFNA(VLOOKUP($B10,'2026年1月21日'!$B:$E,4,0),0) | AJ10: =AI10-AG10 | AK10: =_xlfn.IFNA(VLOOKUP($B10,'2026年1月22日'!$B:$E,4,0),0) | AL10: =AK10-AI10 | AM10: =_xlfn.IFNA(VLOOKUP($B10,'2026年1月23日'!$B:$E,4,0),0) | AN10: =AM10-AK10 | AO10: =_xlfn.IFNA(VLOOKUP($B10,'2026年1月24日'!$B:$E,4,0),0) | AP10: =AO10-AM10 | AQ10: =_xlfn.IFNA(VLOOKUP($B10,'2026年1月26日'!$B:$E,4,0),0) | AR10: =AQ10-AO10 | AS10: 20918600 | AU10: 20938400 | AV10: 19800 | AW10: 20912300 | AX10: -26100 | AY10: 20977500 | AZ10: 65200 | BA10: 20886200 | BB10: -91300 | BC10: 20869500 | BD10: -16700 | BE10: 23724000 | BF10: 2854500 | BG10: 20883400 | BH10: -2840600 | BI10: 23724000 | BJ10: 2840600 | BK10: 20977500 | BL10: -2746500 | BM10: 21912800 | BN10: 935300 | BO10: 21713300 | BP10: -199500 | BQ10: 21713300 | BR10: 0 | BS10: 23279400 | BT10: 1566100 | BU10: 20886200 | BV10: -2393200 | BW10: 20886200 | BX10: 0
B11: B01912 | C11: 核聚證券有限公司 | D11: =_xlfn.IFNA(VLOOKUP($B11,'2026年1月2日'!$B:$E,4,0),0) | E11: =_xlfn.IFNA(VLOOKUP($B11,'2026年1月2日'!$B:$E,4,0),0) | F11: =E11-D11 | G11: =_xlfn.IFNA(VLOOKUP($B11,'2026年1月5日'!$B:$E,4,0),0) | H11: =G11-E11 | I11: =_xlfn.IFNA(VLOOKUP($B11,'2026年1月6日'!$B:$E,4,0),0) | J11: =I11-G11 | K11: =_xlfn.IFNA(VLOOKUP($B11,'2026年1月7日'!$B:$E,4,0),0) | L11: =K11-I11 | M11: =_xlfn.IFNA(VLOOKUP($B11,'2026年1月8日'!$B:$E,4,0),0) | N11: =M11-K11 | O11: =_xlfn.IFNA(VLOOKUP($B11,'2026年1月9日'!$B:$E,4,0),0) | P11: =O11-M11 | Q11: =_xlfn.IFNA(VLOOKUP($B11,'2026年1月10日'!$B:$E,4,0),0) | R11: =Q11-O11 | S11: =_xlfn.IFNA(VLOOKUP($B11,'2026年1月12日'!$B:$E,4,0),0) | T11: =S11-Q11 | U11: =_xlfn.IFNA(VLOOKUP($B11,'2026年1月13日'!$B:$E,4,0),0) | V11: =U11-S11 | W11: =_xlfn.IFNA(VLOOKUP($B11,'2026年1月14日'!$B:$E,4,0),0) | X11: =W11-U11 | Y11: =_xlfn.IFNA(VLOOKUP($B11,'2026年1月15日'!$B:$E,4,0),0) | Z11: =Y11-W11 | AA11: =_xlfn.IFNA(VLOOKUP($B11,'2026年1月16日'!$B:$E,4,0),0) | AB11: =AA11-W11 | AC11: =_xlfn.IFNA(VLOOKUP($B11,'2026年1月17日'!$B:$E,4,0),0) | AD11: =AC11-AA11 | AE11: =_xlfn.IFNA(VLOOKUP($B11,'2026年1月19日'!$B:$E,4,0),0) | AF11: =AE11-AC11 | AG11: =_xlfn.IFNA(VLOOKUP($B11,'2026年1月20日'!$B:$E,4,0),0) | AH11: =AG11-AE11 | AI11: =_xlfn.IFNA(VLOOKUP($B11,'2026年1月21日'!$B:$E,4,0),0) | AJ11: =AI11-AG11 | AK11: =_xlfn.IFNA(VLOOKUP($B11,'2026年1月22日'!$B:$E,4,0),0) | AL11: =AK11-AI11 | AM11: =_xlfn.IFNA(VLOOKUP($B11,'2026年1月23日'!$B:$E,4,0),0) | AN11: =AM11-AK11 | AO11: =_xlfn.IFNA(VLOOKUP($B11,'2026年1月24日'!$B:$E,4,0),0) | AP11: =AO11-AM11 | AQ11: =_xlfn.IFNA(VLOOKUP($B11,'2026年1月26日'!$B:$E,4,0),0) | AR11: =AQ11-AO11 | AS11: 19883897 | AU11: 19883897 | AV11: 0 | AW11: 19883897 | AX11: 0 | AY11: 19883897 | AZ11: 0 | BA11: 19883897 | BB11: 0 | BC11: 19883897 | BD11: 0 | BE11: 19643916 | BF11: -239981 | BG11: 20315016 | BH11: 671100 | BI11: 19643916 | BJ11: -671100 | BK11: 19883897 | BL11: 239981 | BM11: 19833916 | BN11: -49981 | BO11: 19289317 | BP11: -544599 | BQ11: 19289317 | BR11: 0 | BS11: 19795842 | BT11: 506525 | BU11: 19883897 | BV11: 88055 | BW11: 19883897 | BX11: 0
B12: C00010 | C12: 花旗銀行 | D12: =_xlfn.IFNA(VLOOKUP($B12,'2026年1月2日'!$B:$E,4,0),0) | E12: =_xlfn.IFNA(VLOOKUP($B12,'2026年1月2日'!$B:$E,4,0),0) | F12: =E12-D12 | G12: =_xlfn.IFNA(VLOOKUP($B12,'2026年1月5日'!$B:$E,4,0),0) | H12: =G12-E12 | I12: =_xlfn.IFNA(VLOOKUP($B12,'2026年1月6日'!$B:$E,4,0),0) | J12: =I12-G12 | K12: =_xlfn.IFNA(VLOOKUP($B12,'2026年1月7日'!$B:$E,4,0),0) | L12: =K12-I12 | M12: =_xlfn.IFNA(VLOOKUP($B12,'2026年1月8日'!$B:$E,4,0),0) | N12: =M12-K12 | O12: =_xlfn.IFNA(VLOOKUP($B12,'2026年1月9日'!$B:$E,4,0),0) | P12: =O12-M12 | Q12: =_xlfn.IFNA(VLOOKUP($B12,'2026年1月10日'!$B:$E,4,0),0) | R12: =Q12-O12 | S12: =_xlfn.IFNA(VLOOKUP($B12,'2026年1月12日'!$B:$E,4,0),0) | T12: =S12-Q12 | U12: =_xlfn.IFNA(VLOOKUP($B12,'2026年1月13日'!$B:$E,4,0),0) | V12: =U12-S12 | W12: =_xlfn.IFNA(VLOOKUP($B12,'2026年1月14日'!$B:$E,4,0),0) | X12: =W12-U12 | Y12: =_xlfn.IFNA(VLOOKUP($B12,'2026年1月15日'!$B:$E,4,0),0) | Z12: =Y12-W12 | AA12: =_xlfn.IFNA(VLOOKUP($B12,'2026年1月16日'!$B:$E,4,0),0) | AB12: =AA12-W12 | AC12: =_xlfn.IFNA(VLOOKUP($B12,'2026年1月17日'!$B:$E,4,0),0) | AD12: =AC12-AA12 | AE12: =_xlfn.IFNA(VLOOKUP($B12,'2026年1月19日'!$B:$E,4,0),0) | AF12: =AE12-AC12 | AG12: =_xlfn.IFNA(VLOOKUP($B12,'2026年1月20日'!$B:$E,4,0),0) | AH12: =AG12-AE12 | AI12: =_xlfn.IFNA(VLOOKUP($B12,'2026年1月21日'!$B:$E,4,0),0) | AJ12: =AI12-AG12 | AK12: =_xlfn.IFNA(VLOOKUP($B12,'2026年1月22日'!$B:$E,4,0),0) | AL12: =AK12-AI12 | AM12: =_xlfn.IFNA(VLOOKUP($B12,'2026年1月23日'!$B:$E,4,0),0) | AN12: =AM12-AK12 | AO12: =_xlfn.IFNA(VLOOKUP($B12,'2026年1月24日'!$B:$E,4,0),0) | AP12: =AO12-AM12 | AQ12: =_xlfn.IFNA(VLOOKUP($B12,'2026年1月26日'!$B:$E,4,0),0) | AR12: =AQ12-AO12 | AS12: 24615911 | AU12: 25465144 | AV12: 849233 | AW12: 23874326 | AX12: -1590818 | AY12: 24279548 | AZ12: 405222 | BA12: 22680945 | BB12: -1598603 | BC12: 23215345 | BD12: 534400 | BE12: 21695290 | BF12: -1520055 | BG12: 19653679 | BH12: -2041611 | BI12: 21695290 | BJ12: 2041611 | BK12: 24279548 | BL12: 2584258 | BM12: 18486615 | BN12: -5792933 | BO12: 20737157 | BP12: 2250542 | BQ12: 20737157 | BR12: 0 | BS12: 12610040 | BT12: -8127117 | BU12: 22680945 | BV12: 10070905 | BW12: 22680945 | BX12: 0
B13: B01161 | C13: UBS SECURITIES HONG KONG LTD | D13: =_xlfn.IFNA(VLOOKUP($B13,'2026年1月2日'!$B:$E,4,0),0) | E13: =_xlfn.IFNA(VLOOKUP($B13,'2026年1月2日'!$B:$E,4,0),0) | F13: =E13-D13 | G13: =_xlfn.IFNA(VLOOKUP($B13,'2026年1月5日'!$B:$E,4,0),0) | H13: =G13-E13 | I13: =_xlfn.IFNA(VLOOKUP($B13,'2026年1月6日'!$B:$E,4,0),0) | J13: =I13-G13 | K13: =_xlfn.IFNA(VLOOKUP($B13,'2026年1月7日'!$B:$E,4,0),0) | L13: =K13-I13 | M13: =_xlfn.IFNA(VLOOKUP($B13,'2026年1月8日'!$B:$E,4,0),0) | N13: =M13-K13 | O13: =_xlfn.IFNA(VLOOKUP($B13,'2026年1月9日'!$B:$E,4,0),0) | P13: =O13-M13 | Q13: =_xlfn.IFNA(VLOOKUP($B13,'2026年1月10日'!$B:$E,4,0),0) | R13: =Q13-O13 | S13: =_xlfn.IFNA(VLOOKUP($B13,'2026年1月12日'!$B:$E,4,0),0) | T13: =S13-Q13 | U13: =_xlfn.IFNA(VLOOKUP($B13,'2026年1月13日'!$B:$E,4,0),0) | V13: =U13-S13 | W13: =_xlfn.IFNA(VLOOKUP($B13,'2026年1月14日'!$B:$E,4,0),0) | X13: =W13-U13 | Y13: =_xlfn.IFNA(VLOOKUP($B13,'2026年1月15日'!$B:$E,4,0),0) | Z13: =Y13-W13 | AA13: =_xlfn.IFNA(VLOOKUP($B13,'2026年1月16日'!$B:$E,4,0),0) | AB13: =AA13-W13 | AC13: =_xlfn.IFNA(VLOOKUP($B13,'2026年1月17日'!$B:$E,4,0),0) | AD13: =AC13-AA13 | AE13: =_xlfn.IFNA(VLOOKUP($B13,'2026年1月19日'!$B:$E,4,0),0) | AF13: =AE13-AC13 | AG13: =_xlfn.IFNA(VLOOKUP($B13,'2026年1月20日'!$B:$E,4,0),0) | AH13: =AG13-AE13 | AI13: =_xlfn.IFNA(VLOOKUP($B13,'2026年1月21日'!$B:$E,4,0),0) | AJ13: =AI13-AG13 | AK13: =_xlfn.IFNA(VLOOKUP($B13,'2026年1月22日'!$B:$E,4,0),0) | AL13: =AK13-AI13 | AM13: =_xlfn.IFNA(VLOOKUP($B13,'2026年1月23日'!$B:$E,4,0),0) | AN13: =AM13-AK13 | AO13: =_xlfn.IFNA(VLOOKUP($B13,'2026年1月24日'!$B:$E,4,0),0) | AP13: =AO13-AM13 | AQ13: =_xlfn.IFNA(VLOOKUP($B13,'2026年1月26日'!$B:$E,4,0),0) | AR13: =AQ13-AO13 | AS13: 2204036 | AU13: 2156087 | AV13: -47949 | AW13: 2176087 | AX13: 20000 | AY13: 2176037 | AZ13: -50 | BA13: 2202103 | BB13: 26066 | BE13: 2334631 | BG13: 2154892 | BH13: -179739 | BI13: 2334631 | BJ13: 179739 | BK13: 2176037 | BL13: -158594 | BM13: 2736602 | BN13: 560565 | BO13: 2137497 | BP13: -599105 | BQ13: 2137497 | BR13: 0 | BS13: 2184592 | BT13: 47095 | BU13: 2202103 | BV13: 17511 | BW13: 2202103 | BX13: 0
B14: B01901 | C14: 招銀國際證券有限公司 | D14: =_xlfn.IFNA(VLOOKUP($B14,'2026年1月2日'!$B:$E,4,0),0) | E14: =_xlfn.IFNA(VLOOKUP($B14,'2026年1月2日'!$B:$E,4,0),0) | F14: =E14-D14 | G14: =_xlfn.IFNA(VLOOKUP($B14,'2026年1月5日'!$B:$E,4,0),0) | H14: =G14-E14 | I14: =_xlfn.IFNA(VLOOKUP($B14,'2026年1月6日'!$B:$E,4,0),0) | J14: =I14-G14 | K14: =_xlfn.IFNA(VLOOKUP($B14,'2026年1月7日'!$B:$E,4,0),0) | L14: =K14-I14 | M14: =_xlfn.IFNA(VLOOKUP($B14,'2026年1月8日'!$B:$E,4,0),0) | N14: =M14-K14 | O14: =_xlfn.IFNA(VLOOKUP($B14,'2026年1月9日'!$B:$E,4,0),0) | P14: =O14-M14 | Q14: =_xlfn.IFNA(VLOOKUP($B14,'2026年1月10日'!$B:$E,4,0),0) | R14: =Q14-O14 | S14: =_xlfn.IFNA(VLOOKUP($B14,'2026年1月12日'!$B:$E,4,0),0) | T14: =S14-Q14 | U14: =_xlfn.IFNA(VLOOKUP($B14,'2026年1月13日'!$B:$E,4,0),0) | V14: =U14-S14 | W14: =_xlfn.IFNA(VLOOKUP($B14,'2026年1月14日'!$B:$E,4,0),0) | X14: =W14-U14 | Y14: =_xlfn.IFNA(VLOOKUP($B14,'2026年1月15日'!$B:$E,4,0),0) | Z14: =Y14-W14 | AA14: =_xlfn.IFNA(VLOOKUP($B14,'2026年1月16日'!$B:$E,4,0),0) | AB14: =AA14-W14 | AC14: =_xlfn.IFNA(VLOOKUP($B14,'2026年1月17日'!$B:$E,4,0),0) | AD14: =AC14-AA14 | AE14: =_xlfn.IFNA(VLOOKUP($B14,'2026年1月19日'!$B:$E,4,0),0) | AF14: =AE14-AC14 | AG14: =_xlfn.IFNA(VLOOKUP($B14,'2026年1月20日'!$B:$E,4,0),0) | AH14: =AG14-AE14 | AI14: =_xlfn.IFNA(VLOOKUP($B14,'2026年1月21日'!$B:$E,4,0),0) | AJ14: =AI14-AG14 | AK14: =_xlfn.IFNA(VLOOKUP($B14,'2026年1月22日'!$B:$E,4,0),0) | AL14: =AK14-AI14 | AM14: =_xlfn.IFNA(VLOOKUP($B14,'2026年1月23日'!$B:$E,4,0),0) | AN14: =AM14-AK14 | AO14: =_xlfn.IFNA(VLOOKUP($B14,'2026年1月24日'!$B:$E,4,0),0) | AP14: =AO14-AM14 | AQ14: =_xlfn.IFNA(VLOOKUP($B14,'2026年1月26日'!$B:$E,4,0),0) | AR14: =AQ14-AO14 | AS14: 6816190 | AU14: 6816190 | AV14: 0 | AW14: 6816190 | AX14: 0 | AY14: 6816390 | AZ14: 200 | BA14: 6817590 | BB14: 1200 | BC14: 6817590 | BD14: 0 | BE14: 6935990 | BF14: 118400 | BG14: 5858690 | BH14: -1077300 | BI14: 6935990 | BJ14: 1077300 | BK14: 6816390 | BL14: -119600 | BM14: 7174190 | BN14: 357800 | BO14: 5504590 | BP14: -1669600 | BQ14: 5504590 | BR14: 0 | BS14: 5710190 | BT14: 205600 | BU14: 6817590 | BV14: 1107400 | BW14: 6817590 | BX14: 0
B15: B01590 | C15: 盈透證券香港有限公司 | D15: =_xlfn.IFNA(VLOOKUP($B15,'2026年1月2日'!$B:$E,4,0),0) | E15: =_xlfn.IFNA(VLOOKUP($B15,'2026年1月2日'!$B:$E,4,0),0) | F15: =E15-D15 | G15: =_xlfn.IFNA(VLOOKUP($B15,'2026年1月5日'!$B:$E,4,0),0) | H15: =G15-E15 | I15: =_xlfn.IFNA(VLOOKUP($B15,'2026年1月6日'!$B:$E,4,0),0) | J15: =I15-G15 | K15: =_xlfn.IFNA(VLOOKUP($B15,'2026年1月7日'!$B:$E,4,0),0) | L15: =K15-I15 | M15: =_xlfn.IFNA(VLOOKUP($B15,'2026年1月8日'!$B:$E,4,0),0) | N15: =M15-K15 | O15: =_xlfn.IFNA(VLOOKUP($B15,'2026年1月9日'!$B:$E,4,0),0) | P15: =O15-M15 | Q15: =_xlfn.IFNA(VLOOKUP($B15,'2026年1月10日'!$B:$E,4,0),0) | R15: =Q15-O15 | S15: =_xlfn.IFNA(VLOOKUP($B15,'2026年1月12日'!$B:$E,4,0),0) | T15: =S15-Q15 | U15: =_xlfn.IFNA(VLOOKUP($B15,'2026年1月13日'!$B:$E,4,0),0) | V15: =U15-S15 | W15: =_xlfn.IFNA(VLOOKUP($B15,'2026年1月14日'!$B:$E,4,0),0) | X15: =W15-U15 | Y15: =_xlfn.IFNA(VLOOKUP($B15,'2026年1月15日'!$B:$E,4,0),0) | Z15: =Y15-W15 | AA15: =_xlfn.IFNA(VLOOKUP($B15,'2026年1月16日'!$B:$E,4,0),0) | AB15: =AA15-W15 | AC15: =_xlfn.IFNA(VLOOKUP($B15,'2026年1月17日'!$B:$E,4,0),0) | AD15: =AC15-AA15 | AE15: =_xlfn.IFNA(VLOOKUP($B15,'2026年1月19日'!$B:$E,4,0),0) | AF15: =AE15-AC15 | AG15: =_xlfn.IFNA(VLOOKUP($B15,'2026年1月20日'!$B:$E,4,0),0) | AH15: =AG15-AE15 | AI15: =_xlfn.IFNA(VLOOKUP($B15,'2026年1月21日'!$B:$E,4,0),0) | AJ15: =AI15-AG15 | AK15: =_xlfn.IFNA(VLOOKUP($B15,'2026年1月22日'!$B:$E,4,0),0) | AL15: =AK15-AI15 | AM15: =_xlfn.IFNA(VLOOKUP($B15,'2026年1月23日'!$B:$E,4,0),0) | AN15: =AM15-AK15 | AO15: =_xlfn.IFNA(VLOOKUP($B15,'2026年1月24日'!$B:$E,4,0),0) | AP15: =AO15-AM15 | AQ15: =_xlfn.IFNA(VLOOKUP($B15,'2026年1月26日'!$B:$E,4,0),0) | AR15: =AQ15-AO15 | AS15: 1911100 | AU15: 968400 | AV15: -942700 | AW15: 1129700 | AX15: 161300 | AY15: 1099000 | AZ15: -30700 | BA15: 1228393 | BB15: 129393 | BE15: 1003188 | BG15: 657719 | BH15: -345469 | BI15: 1003188 | BJ15: 345469 | BK15: 1099000 | BL15: 95812 | BM15: 908522 | BN15: -190478 | BO15: 1071888 | BP15: 163366 | BQ15: 1071888 | BR15: 0 | BS15: 1033688 | BT15: -38200 | BU15: 1228393 | BV15: 194705 | BW15: 1228393 | BX15: 0
B16: C00039 | C16: 渣打銀行(香港)有限公司 | D16: =_xlfn.IFNA(VLOOKUP($B16,'2026年1月2日'!$B:$E,4,0),0) | E16: =_xlfn.IFNA(VLOOKUP($B16,'2026年1月2日'!$B:$E,4,0),0) | F16: =E16-D16 | G16: =_xlfn.IFNA(VLOOKUP($B16,'2026年1月5日'!$B:$E,4,0),0) | H16: =G16-E16 | I16: =_xlfn.IFNA(VLOOKUP($B16,'2026年1月6日'!$B:$E,4,0),0) | J16: =I16-G16 | K16: =_xlfn.IFNA(VLOOKUP($B16,'2026年1月7日'!$B:$E,4,0),0) | L16: =K16-I16 | M16: =_xlfn.IFNA(VLOOKUP($B16,'2026年1月8日'!$B:$E,4,0),0) | N16: =M16-K16 | O16: =_xlfn.IFNA(VLOOKUP($B16,'2026年1月9日'!$B:$E,4,0),0) | P16: =O16-M16 | Q16: =_xlfn.IFNA(VLOOKUP($B16,'2026年1月10日'!$B:$E,4,0),0) | R16: =Q16-O16 | S16: =_xlfn.IFNA(VLOOKUP($B16,'2026年1月12日'!$B:$E,4,0),0) | T16: =S16-Q16 | U16: =_xlfn.IFNA(VLOOKUP($B16,'2026年1月13日'!$B:$E,4,0),0) | V16: =U16-S16 | W16: =_xlfn.IFNA(VLOOKUP($B16,'2026年1月14日'!$B:$E,4,0),0) | X16: =W16-U16 | Y16: =_xlfn.IFNA(VLOOKUP($B16,'2026年1月15日'!$B:$E,4,0),0) | Z16: =Y16-W16 | AA16: =_xlfn.IFNA(VLOOKUP($B16,'2026年1月16日'!$B:$E,4,0),0) | AB16: =AA16-W16 | AC16: =_xlfn.IFNA(VLOOKUP($B16,'2026年1月17日'!$B:$E,4,0),0) | AD16: =AC16-AA16 | AE16: =_xlfn.IFNA(VLOOKUP($B16,'2026年1月19日'!$B:$E,4,0),0) | AF16: =AE16-AC16 | AG16: =_xlfn.IFNA(VLOOKUP($B16,'2026年1月20日'!$B:$E,4,0),0) | AH16: =AG16-AE16 | AI16: =_xlfn.IFNA(VLOOKUP($B16,'2026年1月21日'!$B:$E,4,0),0) | AJ16: =AI16-AG16 | AK16: =_xlfn.IFNA(VLOOKUP($B16,'2026年1月22日'!$B:$E,4,0),0) | AL16: =AK16-AI16 | AM16: =_xlfn.IFNA(VLOOKUP($B16,'2026年1月23日'!$B:$E,4,0),0) | AN16: =AM16-AK16 | AO16: =_xlfn.IFNA(VLOOKUP($B16,'2026年1月24日'!$B:$E,4,0),0) | AP16: =AO16-AM16 | AQ16: =_xlfn.IFNA(VLOOKUP($B16,'2026年1月26日'!$B:$E,4,0),0) | AR16: =AQ16-AO16 | AS16: 9893437 | AU16: 9875337 | AV16: -18100 | AW16: 9855237 | AX16: -20100 | AY16: 9825737 | AZ16: -29500 | BA16: 9815437 | BB16: -10300 | BC16: 9823437 | BD16: 8000 | BE16: 10279729 | BF16: 456292 | BG16: 8626387 | BH16: -1653342 | BI16: 10279729 | BJ16: 1653342 | BK16: 9825737 | BL16: -453992 | BM16: 9350435 | BN16: -475302 | BO16: 8758389 | BP16: -592046 | BQ16: 8758389 | BR16: 0 | BS16: 8772987 | BT16: 14598 | BU16: 9815437 | BV16: 1042450 | BW16: 9815437 | BX16: 0
B17: B01284 | C17: 恒生證券有限公司 | D17: =_xlfn.IFNA(VLOOKUP($B17,'2026年1月2日'!$B:$E,4,0),0) | E17: =_xlfn.IFNA(VLOOKUP($B17,'2026年1月2日'!$B:$E,4,0),0) | F17: =E17-D17 | G17: =_xlfn.IFNA(VLOOKUP($B17,'2026年1月5日'!$B:$E,4,0),0) | H17: =G17-E17 | I17: =_xlfn.IFNA(VLOOKUP($B17,'2026年1月6日'!$B:$E,4,0),0) | J17: =I17-G17 | K17: =_xlfn.IFNA(VLOOKUP($B17,'2026年1月7日'!$B:$E,4,0),0) | L17: =K17-I17 | M17: =_xlfn.IFNA(VLOOKUP($B17,'2026年1月8日'!$B:$E,4,0),0) | N17: =M17-K17 | O17: =_xlfn.IFNA(VLOOKUP($B17,'2026年1月9日'!$B:$E,4,0),0) | P17: =O17-M17 | Q17: =_xlfn.IFNA(VLOOKUP($B17,'2026年1月10日'!$B:$E,4,0),0) | R17: =Q17-O17 | S17: =_xlfn.IFNA(VLOOKUP($B17,'2026年1月12日'!$B:$E,4,0),0) | T17: =S17-Q17 | U17: =_xlfn.IFNA(VLOOKUP($B17,'2026年1月13日'!$B:$E,4,0),0) | V17: =U17-S17 | W17: =_xlfn.IFNA(VLOOKUP($B17,'2026年1月14日'!$B:$E,4,0),0) | X17: =W17-U17 | Y17: =_xlfn.IFNA(VLOOKUP($B17,'2026年1月15日'!$B:$E,4,0),0) | Z17: =Y17-W17 | AA17: =_xlfn.IFNA(VLOOKUP($B17,'2026年1月16日'!$B:$E,4,0),0) | AB17: =AA17-W17 | AC17: =_xlfn.IFNA(VLOOKUP($B17,'2026年1月17日'!$B:$E,4,0),0) | AD17: =AC17-AA17 | AE17: =_xlfn.IFNA(VLOOKUP($B17,'2026年1月19日'!$B:$E,4,0),0) | AF17: =AE17-AC17 | AG17: =_xlfn.IFNA(VLOOKUP($B17,'2026年1月20日'!$B:$E,4,0),0) | AH17: =AG17-AE17 | AI17: =_xlfn.IFNA(VLOOKUP($B17,'2026年1月21日'!$B:$E,4,0),0) | AJ17: =AI17-AG17 | AK17: =_xlfn.IFNA(VLOOKUP($B17,'2026年1月22日'!$B:$E,4,0),0) | AL17: =AK17-AI17 | AM17: =_xlfn.IFNA(VLOOKUP($B17,'2026年1月23日'!$B:$E,4,0),0) | AN17: =AM17-AK17 | AO17: =_xlfn.IFNA(VLOOKUP($B17,'2026年1月24日'!$B:$E,4,0),0) | AP17: =AO17-AM17 | AQ17: =_xlfn.IFNA(VLOOKUP($B17,'2026年1月26日'!$B:$E,4,0),0) | AR17: =AQ17-AO17 | AS17: 8821500 | AU17: 8820700 | AV17: -800 | AW17: 8836700 | AX17: 16000 | AY17: 8823000 | AZ17: -13700 | BA17: 8850500 | BB17: 27500 | BC17: 8846600 | BD17: -3900 | BE17: 9697100 | BF17: 850500 | BG17: 9391400 | BH17: -305700 | BI17: 9697100 | BJ17: 305700 | BK17: 8823000 | BL17: -874100 | BM17: 9888100 | BN17: 1065100 | BO17: 9351600 | BP17: -536500 | BQ17: 9351600 | BR17: 0 | BS17: 9778500 | BT17: 426900 | BU17: 8850500 | BV17: -928000 | BW17: 8850500 | BX17: 0
B18: C00093 | C18: BNP PARIBAS SECURITIES SERVICES | D18: =_xlfn.IFNA(VLOOKUP($B18,'2026年1月2日'!$B:$E,4,0),0) | E18: =_xlfn.IFNA(VLOOKUP($B18,'2026年1月2日'!$B:$E,4,0),0) | F18: =E18-D18 | G18: =_xlfn.IFNA(VLOOKUP($B18,'2026年1月5日'!$B:$E,4,0),0) | H18: =G18-E18 | I18: =_xlfn.IFNA(VLOOKUP($B18,'2026年1月6日'!$B:$E,4,0),0) | J18: =I18-G18 | K18: =_xlfn.IFNA(VLOOKUP($B18,'2026年1月7日'!$B:$E,4,0),0) | L18: =K18-I18 | M18: =_xlfn.IFNA(VLOOKUP($B18,'2026年1月8日'!$B:$E,4,0),0) | N18: =M18-K18 | O18: =_xlfn.IFNA(VLOOKUP($B18,'2026年1月9日'!$B:$E,4,0),0) | P18: =O18-M18 | Q18: =_xlfn.IFNA(VLOOKUP($B18,'2026年1月10日'!$B:$E,4,0),0) | R18: =Q18-O18 | S18: =_xlfn.IFNA(VLOOKUP($B18,'2026年1月12日'!$B:$E,4,0),0) | T18: =S18-Q18 | U18: =_xlfn.IFNA(VLOOKUP($B18,'2026年1月13日'!$B:$E,4,0),0) | V18: =U18-S18 | W18: =_xlfn.IFNA(VLOOKUP($B18,'2026年1月14日'!$B:$E,4,0),0) | X18: =W18-U18 | Y18: =_xlfn.IFNA(VLOOKUP($B18,'2026年1月15日'!$B:$E,4,0),0) | Z18: =Y18-W18 | AA18: =_xlfn.IFNA(VLOOKUP($B18,'2026年1月16日'!$B:$E,4,0),0) | AB18: =AA18-W18 | AC18: =_xlfn.IFNA(VLOOKUP($B18,'2026年1月17日'!$B:$E,4,0),0) | AD18: =AC18-AA18 | AE18: =_xlfn.IFNA(VLOOKUP($B18,'2026年1月19日'!$B:$E,4,0),0) | AF18: =AE18-AC18 | AG18: =_xlfn.IFNA(VLOOKUP($B18,'2026年1月20日'!$B:$E,4,0),0) | AH18: =AG18-AE18 | AI18: =_xlfn.IFNA(VLOOKUP($B18,'2026年1月21日'!$B:$E,4,0),0) | AJ18: =AI18-AG18 | AK18: =_xlfn.IFNA(VLOOKUP($B18,'2026年1月22日'!$B:$E,4,0),0) | AL18: =AK18-AI18 | AM18: =_xlfn.IFNA(VLOOKUP($B18,'2026年1月23日'!$B:$E,4,0),0) | AN18: =AM18-AK18 | AO18: =_xlfn.IFNA(VLOOKUP($B18,'2026年1月24日'!$B:$E,4,0),0) | AP18: =AO18-AM18 | AQ18: =_xlfn.IFNA(VLOOKUP($B18,'2026年1月26日'!$B:$E,4,0),0) | AR18: =AQ18-AO18 | AS18: 1021828 | AU18: 786428 | AV18: -235400 | AW18: 1583128 | AX18: 796700 | AY18: 2245528 | AZ18: 662400 | BA18: 2507028 | BB18: 261500 | BE18: 1842382 | BG18: 424982 | BH18: -1417400 | BI18: 1842382 | BJ18: 1417400 | BK18: 2245528 | BL18: 403146 | BM18: 1954467 | BN18: -291061 | BO18: 174901 | BP18: -1779566 | BQ18: 174901 | BR18: 0 | BS18: 340692 | BT18: 165791 | BU18: 2507028 | BV18: 2166336 | BW18: 2507028 | BX18: 0
B19: B01130 | C19: 中銀國際證券有限公司 | D19: =_xlfn.IFNA(VLOOKUP($B19,'2026年1月2日'!$B:$E,4,0),0) | E19: =_xlfn.IFNA(VLOOKUP($B19,'2026年1月2日'!$B:$E,4,0),0) | F19: =E19-D19 | G19: =_xlfn.IFNA(VLOOKUP($B19,'2026年1月5日'!$B:$E,4,0),0) | H19: =G19-E19 | I19: =_xlfn.IFNA(VLOOKUP($B19,'2026年1月6日'!$B:$E,4,0),0) | J19: =I19-G19 | K19: =_xlfn.IFNA(VLOOKUP($B19,'2026年1月7日'!$B:$E,4,0),0) | L19: =K19-I19 | M19: =_xlfn.IFNA(VLOOKUP($B19,'2026年1月8日'!$B:$E,4,0),0) | N19: =M19-K19 | O19: =_xlfn.IFNA(VLOOKUP($B19,'2026年1月9日'!$B:$E,4,0),0) | P19: =O19-M19 | Q19: =_xlfn.IFNA(VLOOKUP($B19,'2026年1月10日'!$B:$E,4,0),0) | R19: =Q19-O19 | S19: =_xlfn.IFNA(VLOOKUP($B19,'2026年1月12日'!$B:$E,4,0),0) | T19: =S19-Q19 | U19: =_xlfn.IFNA(VLOOKUP($B19,'2026年1月13日'!$B:$E,4,0),0) | V19: =U19-S19 | W19: =_xlfn.IFNA(VLOOKUP($B19,'2026年1月14日'!$B:$E,4,0),0) | X19: =W19-U19 | Y19: =_xlfn.IFNA(VLOOKUP($B19,'2026年1月15日'!$B:$E,4,0),0) | Z19: =Y19-W19 | AA19: =_xlfn.IFNA(VLOOKUP($B19,'2026年1月16日'!$B:$E,4,0),0) | AB19: =AA19-W19 | AC19: =_xlfn.IFNA(VLOOKUP($B19,'2026年1月17日'!$B:$E,4,0),0) | AD19: =AC19-AA19 | AE19: =_xlfn.IFNA(VLOOKUP($B19,'2026年1月19日'!$B:$E,4,0),0) | AF19: =AE19-AC19 | AG19: =_xlfn.IFNA(VLOOKUP($B19,'2026年1月20日'!$B:$E,4,0),0) | AH19: =AG19-AE19 | AI19: =_xlfn.IFNA(VLOOKUP($B19,'2026年1月21日'!$B:$E,4,0),0) | AJ19: =AI19-AG19 | AK19: =_xlfn.IFNA(VLOOKUP($B19,'2026年1月22日'!$B:$E,4,0),0) | AL19: =AK19-AI19 | AM19: =_xlfn.IFNA(VLOOKUP($B19,'2026年1月23日'!$B:$E,4,0),0) | AN19: =AM19-AK19 | AO19: =_xlfn.IFNA(VLOOKUP($B19,'2026年1月24日'!$B:$E,4,0),0) | AP19: =AO19-AM19 | AQ19: =_xlfn.IFNA(VLOOKUP($B19,'2026年1月26日'!$B:$E,4,0),0) | AR19: =AQ19-AO19 | AS19: 5766000 | AU19: 5761500 | AV19: -4500 | AW19: 5769000 | AX19: 7500 | AY19: 5750100 | AZ19: -18900 | BA19: 5812500 | BB19: 62400 | BC19: 5781600 | BD19: -30900 | BE19: 7326000 | BF19: 1544400 | BG19: 6971900 | BH19: -354100 | BI19: 7326000 | BJ19: 354100 | BK19: 5750100 | BL19: -1575900 | BM19: 7298700 | BN19: 1548600 | BO19: 7017600 | BP19: -281100 | BQ19: 7017600 | BR19: 0 | BS19: 7575800 | BT19: 558200 | BU19: 5812500 | BV19: -1763300 | BW19: 5812500 | BX19: 0
B20: B01668 | C20: 耀才證券國際(香港)有限公司 | D20: =_xlfn.IFNA(VLOOKUP($B20,'2026年1月2日'!$B:$E,4,0),0) | E20: =_xlfn.IFNA(VLOOKUP($B20,'2026年1月2日'!$B:$E,4,0),0) | F20: =E20-D20 | G20: =_xlfn.IFNA(VLOOKUP($B20,'2026年1月5日'!$B:$E,4,0),0) | H20: =G20-E20 | I20: =_xlfn.IFNA(VLOOKUP($B20,'2026年1月6日'!$B:$E,4,0),0) | J20: =I20-G20 | K20: =_xlfn.IFNA(VLOOKUP($B20,'2026年1月7日'!$B:$E,4,0),0) | L20: =K20-I20 | M20: =_xlfn.IFNA(VLOOKUP($B20,'2026年1月8日'!$B:$E,4,0),0) | N20: =M20-K20 | O20: =_xlfn.IFNA(VLOOKUP($B20,'2026年1月9日'!$B:$E,4,0),0) | P20: =O20-M20 | Q20: =_xlfn.IFNA(VLOOKUP($B20,'2026年1月10日'!$B:$E,4,0),0) | R20: =Q20-O20 | S20: =_xlfn.IFNA(VLOOKUP($B20,'2026年1月12日'!$B:$E,4,0),0) | T20: =S20-Q20 | U20: =_xlfn.IFNA(VLOOKUP($B20,'2026年1月13日'!$B:$E,4,0),0) | V20: =U20-S20 | W20: =_xlfn.IFNA(VLOOKUP($B20,'2026年1月14日'!$B:$E,4,0),0) | X20: =W20-U20 | Y20: =_xlfn.IFNA(VLOOKUP($B20,'2026年1月15日'!$B:$E,4,0),0) | Z20: =Y20-W20 | AA20: =_xlfn.IFNA(VLOOKUP($B20,'2026年1月16日'!$B:$E,4,0),0) | AB20: =AA20-W20 | AC20: =_xlfn.IFNA(VLOOKUP($B20,'2026年1月17日'!$B:$E,4,0),0) | AD20: =AC20-AA20 | AE20: =_xlfn.IFNA(VLOOKUP($B20,'2026年1月19日'!$B:$E,4,0),0) | AF20: =AE20-AC20 | AG20: =_xlfn.IFNA(VLOOKUP($B20,'2026年1月20日'!$B:$E,4,0),0) | AH20: =AG20-AE20 | AI20: =_xlfn.IFNA(VLOOKUP($B20,'2026年1月21日'!$B:$E,4,0),0) | AJ20: =AI20-AG20 | AK20: =_xlfn.IFNA(VLOOKUP($B20,'2026年1月22日'!$B:$E,4,0),0) | AL20: =AK20-AI20 | AM20: =_xlfn.IFNA(VLOOKUP($B20,'2026年1月23日'!$B:$E,4,0),0) | AN20: =AM20-AK20 | AO20: =_xlfn.IFNA(VLOOKUP($B20,'2026年1月24日'!$B:$E,4,0),0) | AP20: =AO20-AM20 | AQ20: =_xlfn.IFNA(VLOOKUP($B20,'2026年1月26日'!$B:$E,4,0),0) | AR20: =AQ20-AO20 | AS20: 4475600 | AU20: 4472800 | AV20: -2800 | AW20: 4470400 | AX20: -2400 | AY20: 4482700 | AZ20: 12300 | BA20: 4537400 | BB20: 54700 | BE20: 5157900 | BG20: 4490400 | BH20: -667500 | BI20: 5157900 | BJ20: 667500 | BK20: 4482700 | BL20: -675200 | BM20: 4634200 | BN20: 151500 | BO20: 3815700 | BP20: -818500 | BQ20: 3815700 | BR20: 0 | BS20: 4066900 | BT20: 251200 | BU20: 4537400 | BV20: 470500 | BW20: 4537400 | BX20: 0
B21: B01918 | C21: 偉祿亞太證券有限公司 | D21: =_xlfn.IFNA(VLOOKUP($B21,'2026年1月2日'!$B:$E,4,0),0) | E21: =_xlfn.IFNA(VLOOKUP($B21,'2026年1月2日'!$B:$E,4,0),0) | F21: =E21-D21 | G21: =_xlfn.IFNA(VLOOKUP($B21,'2026年1月5日'!$B:$E,4,0),0) | H21: =G21-E21 | I21: =_xlfn.IFNA(VLOOKUP($B21,'2026年1月6日'!$B:$E,4,0),0) | J21: =I21-G21 | K21: =_xlfn.IFNA(VLOOKUP($B21,'2026年1月7日'!$B:$E,4,0),0) | L21: =K21-I21 | M21: =_xlfn.IFNA(VLOOKUP($B21,'2026年1月8日'!$B:$E,4,0),0) | N21: =M21-K21 | O21: =_xlfn.IFNA(VLOOKUP($B21,'2026年1月9日'!$B:$E,4,0),0) | P21: =O21-M21 | Q21: =_xlfn.IFNA(VLOOKUP($B21,'2026年1月10日'!$B:$E,4,0),0) | R21: =Q21-O21 | S21: =_xlfn.IFNA(VLOOKUP($B21,'2026年1月12日'!$B:$E,4,0),0) | T21: =S21-Q21 | U21: =_xlfn.IFNA(VLOOKUP($B21,'2026年1月13日'!$B:$E,4,0),0) | V21: =U21-S21 | W21: =_xlfn.IFNA(VLOOKUP($B21,'2026年1月14日'!$B:$E,4,0),0) | X21: =W21-U21 | Y21: =_xlfn.IFNA(VLOOKUP($B21,'2026年1月15日'!$B:$E,4,0),0) | Z21: =Y21-W21 | AA21: =_xlfn.IFNA(VLOOKUP($B21,'2026年1月16日'!$B:$E,4,0),0) | AB21: =AA21-W21 | AC21: =_xlfn.IFNA(VLOOKUP($B21,'2026年1月17日'!$B:$E,4,0),0) | AD21: =AC21-AA21 | AE21: =_xlfn.IFNA(VLOOKUP($B21,'2026年1月19日'!$B:$E,4,0),0) | AF21: =AE21-AC21 | AG21: =_xlfn.IFNA(VLOOKUP($B21,'2026年1月20日'!$B:$E,4,0),0) | AH21: =AG21-AE21 | AI21: =_xlfn.IFNA(VLOOKUP($B21,'2026年1月21日'!$B:$E,4,0),0) | AJ21: =AI21-AG21 | AK21: =_xlfn.IFNA(VLOOKUP($B21,'2026年1月22日'!$B:$E,4,0),0) | AL21: =AK21-AI21 | AM21: =_xlfn.IFNA(VLOOKUP($B21,'2026年1月23日'!$B:$E,4,0),0) | AN21: =AM21-AK21 | AO21: =_xlfn.IFNA(VLOOKUP($B21,'2026年1月24日'!$B:$E,4,0),0) | AP21: =AO21-AM21 | AQ21: =_xlfn.IFNA(VLOOKUP($B21,'2026年1月26日'!$B:$E,4,0),0) | AR21: =AQ21-AO21 | AS21: 824 | AU21: 824 | AV21: 0 | AW21: 824 | AX21: 0 | AY21: 824 | AZ21: 0 | BA21: 824 | BB21: 0 | BE21: 824 | BG21: 824 | BH21: 0 | BI21: 824 | BJ21: 0 | BK21: 824 | BL21: 0 | BM21: 824 | BN21: 0 | BO21: 342124 | BP21: 341300 | BQ21: 342124 | BR21: 0 | BS21: 824 | BT21: -341300 | BU21: 824 | BV21: 0 | BW21: 824 | BX21: 0
B22: B01086 | C22: 新鴻基投資服務有限公司 | D22: =_xlfn.IFNA(VLOOKUP($B22,'2026年1月2日'!$B:$E,4,0),0) | E22: =_xlfn.IFNA(VLOOKUP($B22,'2026年1月2日'!$B:$E,4,0),0) | F22: =E22-D22 | G22: =_xlfn.IFNA(VLOOKUP($B22,'2026年1月5日'!$B:$E,4,0),0) | H22: =G22-E22 | I22: =_xlfn.IFNA(VLOOKUP($B22,'2026年1月6日'!$B:$E,4,0),0) | J22: =I22-G22 | K22: =_xlfn.IFNA(VLOOKUP($B22,'2026年1月7日'!$B:$E,4,0),0) | L22: =K22-I22 | M22: =_xlfn.IFNA(VLOOKUP($B22,'2026年1月8日'!$B:$E,4,0),0) | N22: =M22-K22 | O22: =_xlfn.IFNA(VLOOKUP($B22,'2026年1月9日'!$B:$E,4,0),0) | P22: =O22-M22 | Q22: =_xlfn.IFNA(VLOOKUP($B22,'2026年1月10日'!$B:$E,4,0),0) | R22: =Q22-O22 | S22: =_xlfn.IFNA(VLOOKUP($B22,'2026年1月12日'!$B:$E,4,0),0) | T22: =S22-Q22 | U22: =_xlfn.IFNA(VLOOKUP($B22,'2026年1月13日'!$B:$E,4,0),0) | V22: =U22-S22 | W22: =_xlfn.IFNA(VLOOKUP($B22,'2026年1月14日'!$B:$E,4,0),0) | X22: =W22-U22 | Y22: =_xlfn.IFNA(VLOOKUP($B22,'2026年1月15日'!$B:$E,4,0),0) | Z22: =Y22-W22 | AA22: =_xlfn.IFNA(VLOOKUP($B22,'2026年1月16日'!$B:$E,4,0),0) | AB22: =AA22-W22 | AC22: =_xlfn.IFNA(VLOOKUP($B22,'2026年1月17日'!$B:$E,4,0),0) | AD22: =AC22-AA22 | AE22: =_xlfn.IFNA(VLOOKUP($B22,'2026年1月19日'!$B:$E,4,0),0) | AF22: =AE22-AC22 | AG22: =_xlfn.IFNA(VLOOKUP($B22,'2026年1月20日'!$B:$E,4,0),0) | AH22: =AG22-AE22 | AI22: =_xlfn.IFNA(VLOOKUP($B22,'2026年1月21日'!$B:$E,4,0),0) | AJ22: =AI22-AG22 | AK22: =_xlfn.IFNA(VLOOKUP($B22,'2026年1月22日'!$B:$E,4,0),0) | AL22: =AK22-AI22 | AM22: =_xlfn.IFNA(VLOOKUP($B22,'2026年1月23日'!$B:$E,4,0),0) | AN22: =AM22-AK22 | AO22: =_xlfn.IFNA(VLOOKUP($B22,'2026年1月24日'!$B:$E,4,0),0) | AP22: =AO22-AM22 | AQ22: =_xlfn.IFNA(VLOOKUP($B22,'2026年1月26日'!$B:$E,4,0),0) | AR22: =AQ22-AO22 | AS22: 1987700 | AU22: 1987700 | AV22: 0 | AW22: 1947700 | AX22: -40000 | AY22: 1939700 | AZ22: -8000 | BA22: 1939700 | BB22: 0 | BE22: 1736000 | BG22: 1404500 | BH22: -331500 | BI22: 1736000 | BJ22: 331500 | BK22: 1939700 | BL22: 203700 | BM22: 1955500 | BN22: 15800 | BO22: 1161200 | BP22: -794300 | BQ22: 1161200 | BR22: 0 | BS22: 1174100 | BT22: 12900 | BU22: 1939700 | BV22: 765600 | BW22: 1939700 | BX22: 0
B23: C00088 | C23: 招商銀行股份有限公司 | D23: =_xlfn.IFNA(VLOOKUP($B23,'2026年1月2日'!$B:$E,4,0),0) | E23: =_xlfn.IFNA(VLOOKUP($B23,'2026年1月2日'!$B:$E,4,0),0) | F23: =E23-D23 | G23: =_xlfn.IFNA(VLOOKUP($B23,'2026年1月5日'!$B:$E,4,0),0) | H23: =G23-E23 | I23: =_xlfn.IFNA(VLOOKUP($B23,'2026年1月6日'!$B:$E,4,0),0) | J23: =I23-G23 | K23: =_xlfn.IFNA(VLOOKUP($B23,'2026年1月7日'!$B:$E,4,0),0) | L23: =K23-I23 | M23: =_xlfn.IFNA(VLOOKUP($B23,'2026年1月8日'!$B:$E,4,0),0) | N23: =M23-K23 | O23: =_xlfn.IFNA(VLOOKUP($B23,'2026年1月9日'!$B:$E,4,0),0) | P23: =O23-M23 | Q23: =_xlfn.IFNA(VLOOKUP($B23,'2026年1月10日'!$B:$E,4,0),0) | R23: =Q23-O23 | S23: =_xlfn.IFNA(VLOOKUP($B23,'2026年1月12日'!$B:$E,4,0),0) | T23: =S23-Q23 | U23: =_xlfn.IFNA(VLOOKUP($B23,'2026年1月13日'!$B:$E,4,0),0) | V23: =U23-S23 | W23: =_xlfn.IFNA(VLOOKUP($B23,'2026年1月14日'!$B:$E,4,0),0) | X23: =W23-U23 | Y23: =_xlfn.IFNA(VLOOKUP($B23,'2026年1月15日'!$B:$E,4,0),0) | Z23: =Y23-W23 | AA23: =_xlfn.IFNA(VLOOKUP($B23,'2026年1月16日'!$B:$E,4,0),0) | AB23: =AA23-W23 | AC23: =_xlfn.IFNA(VLOOKUP($B23,'2026年1月17日'!$B:$E,4,0),0) | AD23: =AC23-AA23 | AE23: =_xlfn.IFNA(VLOOKUP($B23,'2026年1月19日'!$B:$E,4,0),0) | AF23: =AE23-AC23 | AG23: =_xlfn.IFNA(VLOOKUP($B23,'2026年1月20日'!$B:$E,4,0),0) | AH23: =AG23-AE23 | AI23: =_xlfn.IFNA(VLOOKUP($B23,'2026年1月21日'!$B:$E,4,0),0) | AJ23: =AI23-AG23 | AK23: =_xlfn.IFNA(VLOOKUP($B23,'2026年1月22日'!$B:$E,4,0),0) | AL23: =AK23-AI23 | AM23: =_xlfn.IFNA(VLOOKUP($B23,'2026年1月23日'!$B:$E,4,0),0) | AN23: =AM23-AK23 | AO23: =_xlfn.IFNA(VLOOKUP($B23,'2026年1月24日'!$B:$E,4,0),0) | AP23: =AO23-AM23 | AQ23: =_xlfn.IFNA(VLOOKUP($B23,'2026年1月26日'!$B:$E,4,0),0) | AR23: =AQ23-AO23 | AS23: 1355500 | AU23: 1386300 | AV23: 30800 | AW23: 1344300 | AX23: -42000 | AY23: 1358500 | AZ23: 14200 | BA23: 1357700 | BB23: -800 | BE23: 1538100 | BG23: 3644200 | BH23: 2106100 | BI23: 1538100 | BJ23: -2106100 | BK23: 1358500 | BL23: -179600 | BM23: 3704600 | BN23: 2346100 | BO23: 3559700 | BP23: -144900 | BQ23: 3559700 | BR23: 0 | BS23: 3775000 | BT23: 215300 | BU23: 1357700 | BV23: -2417300 | BW23: 1357700 | BX23: 0
B24: C00042 | C24: 招商永隆銀行有限公司 | D24: =_xlfn.IFNA(VLOOKUP($B24,'2026年1月2日'!$B:$E,4,0),0) | E24: =_xlfn.IFNA(VLOOKUP($B24,'2026年1月2日'!$B:$E,4,0),0) | F24: =E24-D24 | G24: =_xlfn.IFNA(VLOOKUP($B24,'2026年1月5日'!$B:$E,4,0),0) | H24: =G24-E24 | I24: =_xlfn.IFNA(VLOOKUP($B24,'2026年1月6日'!$B:$E,4,0),0) | J24: =I24-G24 | K24: =_xlfn.IFNA(VLOOKUP($B24,'2026年1月7日'!$B:$E,4,0),0) | L24: =K24-I24 | M24: =_xlfn.IFNA(VLOOKUP($B24,'2026年1月8日'!$B:$E,4,0),0) | N24: =M24-K24 | O24: =_xlfn.IFNA(VLOOKUP($B24,'2026年1月9日'!$B:$E,4,0),0) | P24: =O24-M24 | Q24: =_xlfn.IFNA(VLOOKUP($B24,'2026年1月10日'!$B:$E,4,0),0) | R24: =Q24-O24 | S24: =_xlfn.IFNA(VLOOKUP($B24,'2026年1月12日'!$B:$E,4,0),0) | T24: =S24-Q24 | U24: =_xlfn.IFNA(VLOOKUP($B24,'2026年1月13日'!$B:$E,4,0),0) | V24: =U24-S24 | W24: =_xlfn.IFNA(VLOOKUP($B24,'2026年1月14日'!$B:$E,4,0),0) | X24: =W24-U24 | Y24: =_xlfn.IFNA(VLOOKUP($B24,'2026年1月15日'!$B:$E,4,0),0) | Z24: =Y24-W24 | AA24: =_xlfn.IFNA(VLOOKUP($B24,'2026年1月16日'!$B:$E,4,0),0) | AB24: =AA24-W24 | AC24: =_xlfn.IFNA(VLOOKUP($B24,'2026年1月17日'!$B:$E,4,0),0) | AD24: =AC24-AA24 | AE24: =_xlfn.IFNA(VLOOKUP($B24,'2026年1月19日'!$B:$E,4,0),0) | AF24: =AE24-AC24 | AG24: =_xlfn.IFNA(VLOOKUP($B24,'2026年1月20日'!$B:$E,4,0),0) | AH24: =AG24-AE24 | AI24: =_xlfn.IFNA(VLOOKUP($B24,'2026年1月21日'!$B:$E,4,0),0) | AJ24: =AI24-AG24 | AK24: =_xlfn.IFNA(VLOOKUP($B24,'2026年1月22日'!$B:$E,4,0),0) | AL24: =AK24-AI24 | AM24: =_xlfn.IFNA(VLOOKUP($B24,'2026年1月23日'!$B:$E,4,0),0) | AN24: =AM24-AK24 | AO24: =_xlfn.IFNA(VLOOKUP($B24,'2026年1月24日'!$B:$E,4,0),0) | AP24: =AO24-AM24 | AQ24: =_xlfn.IFNA(VLOOKUP($B24,'2026年1月26日'!$B:$E,4,0),0) | AR24: =AQ24-AO24 | AS24: 4752200 | AU24: 4751200 | AV24: -1000 | AW24: 4775700 | AX24: 24500 | AY24: 4775800 | AZ24: 100 | BA24: 4750100 | BB24: -25700 | BC24: 4748400 | BD24: -1700 | BE24: 5286600 | BF24: 538200 | BG24: 5337900 | BH24: 51300 | BI24: 5286600 | BJ24: -51300 | BK24: 4775800 | BL24: -510800 | BM24: 5866100 | BN24: 1090300 | BO24: 4991200 | BP24: -874900 | BQ24: 4991200 | BR24: 0 | BS24: 5232500 | BT24: 241300 | BU24: 4750100 | BV24: -482400 | BW24: 4750100 | BX24: 0
B25: B01829 | C25: 華泰金融控股(香港)有限公司 | D25: =_xlfn.IFNA(VLOOKUP($B25,'2026年1月2日'!$B:$E,4,0),0) | E25: =_xlfn.IFNA(VLOOKUP($B25,'2026年1月2日'!$B:$E,4,0),0) | F25: =E25-D25 | G25: =_xlfn.IFNA(VLOOKUP($B25,'2026年1月5日'!$B:$E,4,0),0) | H25: =G25-E25 | I25: =_xlfn.IFNA(VLOOKUP($B25,'2026年1月6日'!$B:$E,4,0),0) | J25: =I25-G25 | K25: =_xlfn.IFNA(VLOOKUP($B25,'2026年1月7日'!$B:$E,4,0),0) | L25: =K25-I25 | M25: =_xlfn.IFNA(VLOOKUP($B25,'2026年1月8日'!$B:$E,4,0),0) | N25: =M25-K25 | O25: =_xlfn.IFNA(VLOOKUP($B25,'2026年1月9日'!$B:$E,4,0),0) | P25: =O25-M25 | Q25: =_xlfn.IFNA(VLOOKUP($B25,'2026年1月10日'!$B:$E,4,0),0) | R25: =Q25-O25 | S25: =_xlfn.IFNA(VLOOKUP($B25,'2026年1月12日'!$B:$E,4,0),0) | T25: =S25-Q25 | U25: =_xlfn.IFNA(VLOOKUP($B25,'2026年1月13日'!$B:$E,4,0),0) | V25: =U25-S25 | W25: =_xlfn.IFNA(VLOOKUP($B25,'2026年1月14日'!$B:$E,4,0),0) | X25: =W25-U25 | Y25: =_xlfn.IFNA(VLOOKUP($B25,'2026年1月15日'!$B:$E,4,0),0) | Z25: =Y25-W25 | AA25: =_xlfn.IFNA(VLOOKUP($B25,'2026年1月16日'!$B:$E,4,0),0) | AB25: =AA25-W25 | AC25: =_xlfn.IFNA(VLOOKUP($B25,'2026年1月17日'!$B:$E,4,0),0) | AD25: =AC25-AA25 | AE25: =_xlfn.IFNA(VLOOKUP($B25,'2026年1月19日'!$B:$E,4,0),0) | AF25: =AE25-AC25 | AG25: =_xlfn.IFNA(VLOOKUP($B25,'2026年1月20日'!$B:$E,4,0),0) | AH25: =AG25-AE25 | AI25: =_xlfn.IFNA(VLOOKUP($B25,'2026年1月21日'!$B:$E,4,0),0) | AJ25: =AI25-AG25 | AK25: =_xlfn.IFNA(VLOOKUP($B25,'2026年1月22日'!$B:$E,4,0),0) | AL25: =AK25-AI25 | AM25: =_xlfn.IFNA(VLOOKUP($B25,'2026年1月23日'!$B:$E,4,0),0) | AN25: =AM25-AK25 | AO25: =_xlfn.IFNA(VLOOKUP($B25,'2026年1月24日'!$B:$E,4,0),0) | AP25: =AO25-AM25 | AQ25: =_xlfn.IFNA(VLOOKUP($B25,'2026年1月26日'!$B:$E,4,0),0) | AR25: =AQ25-AO25 | AS25: 1998900 | AU25: 2002400 | AV25: 3500 | AW25: 2000500 | AX25: -1900 | AY25: 1998900 | AZ25: -1600 | BA25: 1998900 | BB25: 0 | BE25: 1869000 | BG25: 2154400 | BH25: 285400 | BI25: 1869000 | BJ25: -285400 | BK25: 1998900 | BL25: 129900 | BM25: 1747000 | BN25: -251900 | BO25: 1734100 | BP25: -12900 | BQ25: 1734100 | BR25: 0 | BS25: 2014700 | BT25: 280600 | BU25: 1998900 | BV25: -15800 | BW25: 1998900 | BX25: 0
B26: B01929 | C26: 中國銀河國際證券(香港)有限公司 | D26: =_xlfn.IFNA(VLOOKUP($B26,'2026年1月2日'!$B:$E,4,0),0) | E26: =_xlfn.IFNA(VLOOKUP($B26,'2026年1月2日'!$B:$E,4,0),0) | F26: =E26-D26 | G26: =_xlfn.IFNA(VLOOKUP($B26,'2026年1月5日'!$B:$E,4,0),0) | H26: =G26-E26 | I26: =_xlfn.IFNA(VLOOKUP($B26,'2026年1月6日'!$B:$E,4,0),0) | J26: =I26-G26 | K26: =_xlfn.IFNA(VLOOKUP($B26,'2026年1月7日'!$B:$E,4,0),0) | L26: =K26-I26 | M26: =_xlfn.IFNA(VLOOKUP($B26,'2026年1月8日'!$B:$E,4,0),0) | N26: =M26-K26 | O26: =_xlfn.IFNA(VLOOKUP($B26,'2026年1月9日'!$B:$E,4,0),0) | P26: =O26-M26 | Q26: =_xlfn.IFNA(VLOOKUP($B26,'2026年1月10日'!$B:$E,4,0),0) | R26: =Q26-O26 | S26: =_xlfn.IFNA(VLOOKUP($B26,'2026年1月12日'!$B:$E,4,0),0) | T26: =S26-Q26 | U26: =_xlfn.IFNA(VLOOKUP($B26,'2026年1月13日'!$B:$E,4,0),0) | V26: =U26-S26 | W26: =_xlfn.IFNA(VLOOKUP($B26,'2026年1月14日'!$B:$E,4,0),0) | X26: =W26-U26 | Y26: =_xlfn.IFNA(VLOOKUP($B26,'2026年1月15日'!$B:$E,4,0),0) | Z26: =Y26-W26 | AA26: =_xlfn.IFNA(VLOOKUP($B26,'2026年1月16日'!$B:$E,4,0),0) | AB26: =AA26-W26 | AC26: =_xlfn.IFNA(VLOOKUP($B26,'2026年1月17日'!$B:$E,4,0),0) | AD26: =AC26-AA26 | AE26: =_xlfn.IFNA(VLOOKUP($B26,'2026年1月19日'!$B:$E,4,0),0) | AF26: =AE26-AC26 | AG26: =_xlfn.IFNA(VLOOKUP($B26,'2026年1月20日'!$B:$E,4,0),0) | AH26: =AG26-AE26 | AI26: =_xlfn.IFNA(VLOOKUP($B26,'2026年1月21日'!$B:$E,4,0),0) | AJ26: =AI26-AG26 | AK26: =_xlfn.IFNA(VLOOKUP($B26,'2026年1月22日'!$B:$E,4,0),0) | AL26: =AK26-AI26 | AM26: =_xlfn.IFNA(VLOOKUP($B26,'2026年1月23日'!$B:$E,4,0),0) | AN26: =AM26-AK26 | AO26: =_xlfn.IFNA(VLOOKUP($B26,'2026年1月24日'!$B:$E,4,0),0) | AP26: =AO26-AM26 | AQ26: =_xlfn.IFNA(VLOOKUP($B26,'2026年1月26日'!$B:$E,4,0),0) | AR26: =AQ26-AO26 | AS26: 149800 | AU26: 149800 | AV26: 0 | AW26: 149800 | AX26: 0 | AY26: 149800 | AZ26: 0 | BA26: 129800 | BB26: -20000 | BE26: 302700 | BG26: 272800 | BH26: -29900 | BI26: 302700 | BJ26: 29900 | BK26: 149800 | BL26: -152900 | BM26: 551800 | BN26: 402000 | BO26: 220000 | BP26: -331800 | BQ26: 220000 | BR26: 0 | BS26: 168800 | BT26: -51200 | BU26: 129800 | BV26: -39000 | BW26: 129800 | BX26: 0
B27: B01727 | C27: 工銀亞洲証券有限公司 | D27: =_xlfn.IFNA(VLOOKUP($B27,'2026年1月2日'!$B:$E,4,0),0) | E27: =_xlfn.IFNA(VLOOKUP($B27,'2026年1月2日'!$B:$E,4,0),0) | F27: =E27-D27 | G27: =_xlfn.IFNA(VLOOKUP($B27,'2026年1月5日'!$B:$E,4,0),0) | H27: =G27-E27 | I27: =_xlfn.IFNA(VLOOKUP($B27,'2026年1月6日'!$B:$E,4,0),0) | J27: =I27-G27 | K27: =_xlfn.IFNA(VLOOKUP($B27,'2026年1月7日'!$B:$E,4,0),0) | L27: =K27-I27 | M27: =_xlfn.IFNA(VLOOKUP($B27,'2026年1月8日'!$B:$E,4,0),0) | N27: =M27-K27 | O27: =_xlfn.IFNA(VLOOKUP($B27,'2026年1月9日'!$B:$E,4,0),0) | P27: =O27-M27 | Q27: =_xlfn.IFNA(VLOOKUP($B27,'2026年1月10日'!$B:$E,4,0),0) | R27: =Q27-O27 | S27: =_xlfn.IFNA(VLOOKUP($B27,'2026年1月12日'!$B:$E,4,0),0) | T27: =S27-Q27 | U27: =_xlfn.IFNA(VLOOKUP($B27,'2026年1月13日'!$B:$E,4,0),0) | V27: =U27-S27 | W27: =_xlfn.IFNA(VLOOKUP($B27,'2026年1月14日'!$B:$E,4,0),0) | X27: =W27-U27 | Y27: =_xlfn.IFNA(VLOOKUP($B27,'2026年1月15日'!$B:$E,4,0),0) | Z27: =Y27-W27 | AA27: =_xlfn.IFNA(VLOOKUP($B27,'2026年1月16日'!$B:$E,4,0),0) | AB27: =AA27-W27 | AC27: =_xlfn.IFNA(VLOOKUP($B27,'2026年1月17日'!$B:$E,4,0),0) | AD27: =AC27-AA27 | AE27: =_xlfn.IFNA(VLOOKUP($B27,'2026年1月19日'!$B:$E,4,0),0) | AF27: =AE27-AC27 | AG27: =_xlfn.IFNA(VLOOKUP($B27,'2026年1月20日'!$B:$E,4,0),0) | AH27: =AG27-AE27 | AI27: =_xlfn.IFNA(VLOOKUP($B27,'2026年1月21日'!$B:$E,4,0),0) | AJ27: =AI27-AG27 | AK27: =_xlfn.IFNA(VLOOKUP($B27,'2026年1月22日'!$B:$E,4,0),0) | AL27: =AK27-AI27 | AM27: =_xlfn.IFNA(VLOOKUP($B27,'2026年1月23日'!$B:$E,4,0),0) | AN27: =AM27-AK27 | AO27: =_xlfn.IFNA(VLOOKUP($B27,'2026年1月24日'!$B:$E,4,0),0) | AP27: =AO27-AM27 | AQ27: =_xlfn.IFNA(VLOOKUP($B27,'2026年1月26日'!$B:$E,4,0),0) | AR27: =AQ27-AO27 | AS27: 2723500 | AU27: 2683400 | AV27: -40100 | AW27: 2674400 | AX27: -9000 | AY27: 2704300 | AZ27: 29900 | BA27: 2652700 | BB27: -51600 | BE27: 3075600 | BG27: 2663900 | BH27: -411700 | BI27: 3075600 | BJ27: 411700 | BK27: 2704300 | BL27: -371300 | BM27: 2541200 | BN27: -163100 | BO27: 2575700 | BP27: 34500 | BQ27: 2575700 | BR27: 0 | BS27: 2844800 | BT27: 269100 | BU27: 2652700 | BV27: -192100 | BW27: 2652700 | BX27: 0
B28: C00002 | C28: 交通銀行信託有限公司 | D28: =_xlfn.IFNA(VLOOKUP($B28,'2026年1月2日'!$B:$E,4,0),0) | E28: =_xlfn.IFNA(VLOOKUP($B28,'2026年1月2日'!$B:$E,4,0),0) | F28: =E28-D28 | G28: =_xlfn.IFNA(VLOOKUP($B28,'2026年1月5日'!$B:$E,4,0),0) | H28: =G28-E28 | I28: =_xlfn.IFNA(VLOOKUP($B28,'2026年1月6日'!$B:$E,4,0),0) | J28: =I28-G28 | K28: =_xlfn.IFNA(VLOOKUP($B28,'2026年1月7日'!$B:$E,4,0),0) | L28: =K28-I28 | M28: =_xlfn.IFNA(VLOOKUP($B28,'2026年1月8日'!$B:$E,4,0),0) | N28: =M28-K28 | O28: =_xlfn.IFNA(VLOOKUP($B28,'2026年1月9日'!$B:$E,4,0),0) | P28: =O28-M28 | Q28: =_xlfn.IFNA(VLOOKUP($B28,'2026年1月10日'!$B:$E,4,0),0) | R28: =Q28-O28 | S28: =_xlfn.IFNA(VLOOKUP($B28,'2026年1月12日'!$B:$E,4,0),0) | T28: =S28-Q28 | U28: =_xlfn.IFNA(VLOOKUP($B28,'2026年1月13日'!$B:$E,4,0),0) | V28: =U28-S28 | W28: =_xlfn.IFNA(VLOOKUP($B28,'2026年1月14日'!$B:$E,4,0),0) | X28: =W28-U28 | Y28: =_xlfn.IFNA(VLOOKUP($B28,'2026年1月15日'!$B:$E,4,0),0) | Z28: =Y28-W28 | AA28: =_xlfn.IFNA(VLOOKUP($B28,'2026年1月16日'!$B:$E,4,0),0) | AB28: =AA28-W28 | AC28: =_xlfn.IFNA(VLOOKUP($B28,'2026年1月17日'!$B:$E,4,0),0) | AD28: =AC28-AA28 | AE28: =_xlfn.IFNA(VLOOKUP($B28,'2026年1月19日'!$B:$E,4,0),0) | AF28: =AE28-AC28 | AG28: =_xlfn.IFNA(VLOOKUP($B28,'2026年1月20日'!$B:$E,4,0),0) | AH28: =AG28-AE28 | AI28: =_xlfn.IFNA(VLOOKUP($B28,'2026年1月21日'!$B:$E,4,0),0) | AJ28: =AI28-AG28 | AK28: =_xlfn.IFNA(VLOOKUP($B28,'2026年1月22日'!$B:$E,4,0),0) | AL28: =AK28-AI28 | AM28: =_xlfn.IFNA(VLOOKUP($B28,'2026年1月23日'!$B:$E,4,0),0) | AN28: =AM28-AK28 | AO28: =_xlfn.IFNA(VLOOKUP($B28,'2026年1月24日'!$B:$E,4,0),0) | AP28: =AO28-AM28 | AQ28: =_xlfn.IFNA(VLOOKUP($B28,'2026年1月26日'!$B:$E,4,0),0) | AR28: =AQ28-AO28 | AS28: 1573400 | AU28: 1573400 | AV28: 0 | AW28: 1577400 | AX28: 4000 | AY28: 1583700 | AZ28: 6300 | BA28: 1587600 | BB28: 3900 | BE28: 2022400 | BG28: 1551000 | BH28: -471400 | BI28: 2022400 | BJ28: 471400 | BK28: 1583700 | BL28: -438700 | BM28: 1587900 | BN28: 4200 | BO28: 1797900 | BP28: 210000 | BQ28: 1797900 | BR28: 0 | BS28: 1828100 | BT28: 30200 | BU28: 1587600 | BV28: -240500 | BW28: 1587600 | BX28: 0
B29: B01345 | C29: 輝立証券(香港)有限公司 | D29: =_xlfn.IFNA(VLOOKUP($B29,'2026年1月2日'!$B:$E,4,0),0) | E29: =_xlfn.IFNA(VLOOKUP($B29,'2026年1月2日'!$B:$E,4,0),0) | F29: =E29-D29 | G29: =_xlfn.IFNA(VLOOKUP($B29,'2026年1月5日'!$B:$E,4,0),0) | H29: =G29-E29 | I29: =_xlfn.IFNA(VLOOKUP($B29,'2026年1月6日'!$B:$E,4,0),0) | J29: =I29-G29 | K29: =_xlfn.IFNA(VLOOKUP($B29,'2026年1月7日'!$B:$E,4,0),0) | L29: =K29-I29 | M29: =_xlfn.IFNA(VLOOKUP($B29,'2026年1月8日'!$B:$E,4,0),0) | N29: =M29-K29 | O29: =_xlfn.IFNA(VLOOKUP($B29,'2026年1月9日'!$B:$E,4,0),0) | P29: =O29-M29 | Q29: =_xlfn.IFNA(VLOOKUP($B29,'2026年1月10日'!$B:$E,4,0),0) | R29: =Q29-O29 | S29: =_xlfn.IFNA(VLOOKUP($B29,'2026年1月12日'!$B:$E,4,0),0) | T29: =S29-Q29 | U29: =_xlfn.IFNA(VLOOKUP($B29,'2026年1月13日'!$B:$E,4,0),0) | V29: =U29-S29 | W29: =_xlfn.IFNA(VLOOKUP($B29,'2026年1月14日'!$B:$E,4,0),0) | X29: =W29-U29 | Y29: =_xlfn.IFNA(VLOOKUP($B29,'2026年1月15日'!$B:$E,4,0),0) | Z29: =Y29-W29 | AA29: =_xlfn.IFNA(VLOOKUP($B29,'2026年1月16日'!$B:$E,4,0),0) | AB29: =AA29-W29 | AC29: =_xlfn.IFNA(VLOOKUP($B29,'2026年1月17日'!$B:$E,4,0),0) | AD29: =AC29-AA29 | AE29: =_xlfn.IFNA(VLOOKUP($B29,'2026年1月19日'!$B:$E,4,0),0) | AF29: =AE29-AC29 | AG29: =_xlfn.IFNA(VLOOKUP($B29,'2026年1月20日'!$B:$E,4,0),0) | AH29: =AG29-AE29 | AI29: =_xlfn.IFNA(VLOOKUP($B29,'2026年1月21日'!$B:$E,4,0),0) | AJ29: =AI29-AG29 | AK29: =_xlfn.IFNA(VLOOKUP($B29,'2026年1月22日'!$B:$E,4,0),0) | AL29: =AK29-AI29 | AM29: =_xlfn.IFNA(VLOOKUP($B29,'2026年1月23日'!$B:$E,4,0),0) | AN29: =AM29-AK29 | AO29: =_xlfn.IFNA(VLOOKUP($B29,'2026年1月24日'!$B:$E,4,0),0) | AP29: =AO29-AM29 | AQ29: =_xlfn.IFNA(VLOOKUP($B29,'2026年1月26日'!$B:$E,4,0),0) | AR29: =AQ29-AO29 | AS29: 2719400 | AU29: 2710100 | AV29: -9300 | AW29: 2714000 | AX29: 3900 | AY29: 2714900 | AZ29: 900 | BA29: 2669900 | BB29: -45000 | BE29: 2775200 | BG29: 2733600 | BH29: -41600 | BI29: 2775200 | BJ29: 41600 | BK29: 2714900 | BL29: -60300 | BM29: 2914700 | BN29: 199800 | BO29: 2272100 | BP29: -642600 | BQ29: 2272100 | BR29: 0 | BS29: 2359700 | BT29: 87600 | BU29: 2669900 | BV29: 310200 | BW29: 2669900 | BX29: 0
B30: C00028 | C30: 南洋商業銀行有限公司 | D30: =_xlfn.IFNA(VLOOKUP($B30,'2026年1月2日'!$B:$E,4,0),0) | E30: =_xlfn.IFNA(VLOOKUP($B30,'2026年1月2日'!$B:$E,4,0),0) | F30: =E30-D30 | G30: =_xlfn.IFNA(VLOOKUP($B30,'2026年1月5日'!$B:$E,4,0),0) | H30: =G30-E30 | I30: =_xlfn.IFNA(VLOOKUP($B30,'2026年1月6日'!$B:$E,4,0),0) | J30: =I30-G30 | K30: =_xlfn.IFNA(VLOOKUP($B30,'2026年1月7日'!$B:$E,4,0),0) | L30: =K30-I30 | M30: =_xlfn.IFNA(VLOOKUP($B30,'2026年1月8日'!$B:$E,4,0),0) | N30: =M30-K30 | O30: =_xlfn.IFNA(VLOOKUP($B30,'2026年1月9日'!$B:$E,4,0),0) | P30: =O30-M30 | Q30: =_xlfn.IFNA(VLOOKUP($B30,'2026年1月10日'!$B:$E,4,0),0) | R30: =Q30-O30 | S30: =_xlfn.IFNA(VLOOKUP($B30,'2026年1月12日'!$B:$E,4,0),0) | T30: =S30-Q30 | U30: =_xlfn.IFNA(VLOOKUP($B30,'2026年1月13日'!$B:$E,4,0),0) | V30: =U30-S30 | W30: =_xlfn.IFNA(VLOOKUP($B30,'2026年1月14日'!$B:$E,4,0),0) | X30: =W30-U30 | Y30: =_xlfn.IFNA(VLOOKUP($B30,'2026年1月15日'!$B:$E,4,0),0) | Z30: =Y30-W30 | AA30: =_xlfn.IFNA(VLOOKUP($B30,'2026年1月16日'!$B:$E,4,0),0) | AB30: =AA30-W30 | AC30: =_xlfn.IFNA(VLOOKUP($B30,'2026年1月17日'!$B:$E,4,0),0) | AD30: =AC30-AA30 | AE30: =_xlfn.IFNA(VLOOKUP($B30,'2026年1月19日'!$B:$E,4,0),0) | AF30: =AE30-AC30 | AG30: =_xlfn.IFNA(VLOOKUP($B30,'2026年1月20日'!$B:$E,4,0),0) | AH30: =AG30-AE30 | AI30: =_xlfn.IFNA(VLOOKUP($B30,'2026年1月21日'!$B:$E,4,0),0) | AJ30: =AI30-AG30 | AK30: =_xlfn.IFNA(VLOOKUP($B30,'2026年1月22日'!$B:$E,4,0),0) | AL30: =AK30-AI30 | AM30: =_xlfn.IFNA(VLOOKUP($B30,'2026年1月23日'!$B:$E,4,0),0) | AN30: =AM30-AK30 | AO30: =_xlfn.IFNA(VLOOKUP($B30,'2026年1月24日'!$B:$E,4,0),0) | AP30: =AO30-AM30 | AQ30: =_xlfn.IFNA(VLOOKUP($B30,'2026年1月26日'!$B:$E,4,0),0) | AR30: =AQ30-AO30 | AS30: 1094200 | AU30: 1091200 | AV30: -3000 | AW30: 1091200 | AX30: 0 | AY30: 1091200 | AZ30: 0 | BA30: 1089200 | BB30: -2000 | BE30: 1194600 | BG30: 1271000 | BH30: 76400 | BI30: 1194600 | BJ30: -76400 | BK30: 1091200 | BL30: -103400 | BM30: 1364600 | BN30: 273400 | BO30: 1300100 | BP30: -64500 | BQ30: 1300100 | BR30: 0 | BS30: 1340200 | BT30: 40100 | BU30: 1089200 | BV30: -251000 | BW30: 1089200 | BX30: 0
